python3: can't open file '/home/sobirjonovmuhammadazizbek/course-bot/bot.py': [Errno 2] No such file or directory
Traceback (most recent call last):
  File "/home/sobirjonovmuhammadazizbek/course-bot/data/bot.py", line 4, in <module>
    from components.CustomInlineMarkup import CustomInlineMarkup
ModuleNotFoundError: No module named 'components'
Traceback (most recent call last):
  File "/home/sobirjonovmuhammadazizbek/course-bot/bot.py", line 1, in <module>
    from telebot import TeleBot
ModuleNotFoundError: No module named 'telebot'
Traceback (most recent call last):
  File "/home/sobirjonovmuhammadazizbek/course-bot/bot.py", line 1, in <module>
    from telebot import TeleBot
ModuleNotFoundError: No module named 'telebot'
1980653792
Traceback (most recent call last):
  File "/home/sobirjonovmuhammadazizbek/course-bot/bot.py", line 159, in <module>
    bot.run()
  File "/home/sobirjonovmuhammadazizbek/course-bot/bot.py", line 154, in run
    self.bot.polling(none_stop=True)
  File "/home/sobirjonovmuhammadazizbek/course-bot/venv/lib/python3.11/site-packages/telebot/__init__.py", line 1104, in polling
    self.__threaded_polling(non_stop=non_stop, interval=interval, timeout=timeout, long_polling_timeout=long_polling_timeout,
  File "/home/sobirjonovmuhammadazizbek/course-bot/venv/lib/python3.11/site-packages/telebot/__init__.py", line 1179, in __threaded_polling
    raise e
  File "/home/sobirjonovmuhammadazizbek/course-bot/venv/lib/python3.11/site-packages/telebot/__init__.py", line 1141, in __threaded_polling
    self.worker_pool.raise_exceptions()
  File "/home/sobirjonovmuhammadazizbek/course-bot/venv/lib/python3.11/site-packages/telebot/util.py", line 149, in raise_exceptions
    raise self.exception_info
  File "/home/sobirjonovmuhammadazizbek/course-bot/venv/lib/python3.11/site-packages/telebot/util.py", line 92, in run
    task(*args, **kwargs)
  File "/home/sobirjonovmuhammadazizbek/course-bot/venv/lib/python3.11/site-packages/telebot/__init__.py", line 7868, in _run_middlewares_and_handler
    result = handler['function'](message)
             ^^^^^^^^^^^^^^^^^^^^^^^^^^^^
  File "/home/sobirjonovmuhammadazizbek/course-bot/bot.py", line 105, in send_welcome
    self.start(message)
  File "/home/sobirjonovmuhammadazizbek/course-bot/bot.py", line 49, in start
    self.db.create_user(str(message.chat.id))
  File "/home/sobirjonovmuhammadazizbek/course-bot/ReferralSystemDBManager.py", line 39, in create_user
    cursor.execute(db.create_user(), (user_id,))
                   ^^^^^^^^^^^^^^
AttributeError: module 'ReferralSystemDBUtils' has no attribute 'create_user'
1980653792
Error creating user: no such table: referrals
{'content_type': 'text', 'id': 430, 'message_id': 430, 'from_user': {'id': 1980653792, 'is_bot': False, 'first_name': 'Islom', 'username': 'eLoving', 'last_name': 'Sheraliyev', 'language_code': 'en', 'can_join_groups': None, 'can_read_all_group_messages': None, 'supports_inline_queries': None, 'is_premium': None, 'added_to_attachment_menu': None}, 'date': 1711829912, 'chat': {'id': 1980653792, 'type': 'private', 'title': None, 'username': 'eLoving', 'first_name': 'Islom', 'last_name': 'Sheraliyev', 'is_forum': None, 'photo': None, 'bio': None, 'join_to_send_messages': None, 'join_by_request': None, 'has_private_forwards': None, 'has_restricted_voice_and_video_messages': None, 'description': None, 'invite_link': None, 'pinned_message': None, 'permissions': None, 'slow_mode_delay': None, 'message_auto_delete_time': None, 'has_protected_content': None, 'sticker_set_name': None, 'can_set_sticker_set': None, 'linked_chat_id': None, 'location': None, 'active_usernames': None, 'emoji_status_custom_emoji_id': None, 'has_hidden_members': None, 'has_aggressive_anti_spam_enabled': None, 'emoji_status_expiration_date': None, 'available_reactions': None, 'accent_color_id': None, 'background_custom_emoji_id': None, 'profile_accent_color_id': None, 'profile_background_custom_emoji_id': None, 'has_visible_history': None, 'unrestrict_boost_count': None, 'custom_emoji_sticker_set_name': None}, 'sender_chat': None, 'is_automatic_forward': None, 'reply_to_message': None, 'via_bot': None, 'edit_date': None, 'has_protected_content': None, 'media_group_id': None, 'author_signature': None, 'text': '/start', 'entities': [<telebot.types.MessageEntity object at 0x7fdb86cc2e90>], 'caption_entities': None, 'audio': None, 'document': None, 'photo': None, 'sticker': None, 'video': None, 'video_note': None, 'voice': None, 'caption': None, 'contact': None, 'location': None, 'venue': None, 'animation': None, 'dice': None, 'new_chat_members': None, 'left_chat_member': None, 'new_chat_title': None, 'new_chat_photo': None, 'delete_chat_photo': None, 'group_chat_created': None, 'supergroup_chat_created': None, 'channel_chat_created': None, 'migrate_to_chat_id': None, 'migrate_from_chat_id': None, 'pinned_message': None, 'invoice': None, 'successful_payment': None, 'connected_website': None, 'reply_markup': None, 'message_thread_id': None, 'is_topic_message': None, 'forum_topic_created': None, 'forum_topic_closed': None, 'forum_topic_reopened': None, 'has_media_spoiler': None, 'forum_topic_edited': None, 'general_forum_topic_hidden': None, 'general_forum_topic_unhidden': None, 'write_access_allowed': None, 'users_shared': None, 'chat_shared': None, 'story': None, 'external_reply': None, 'quote': None, 'link_preview_options': None, 'giveaway_created': None, 'giveaway': None, 'giveaway_winners': None, 'giveaway_completed': None, 'forward_origin': None, 'boost_added': None, 'sender_boost_count': None, 'reply_to_story': None, 'json': {'message_id': 430, 'from': {'id': 1980653792, 'is_bot': False, 'first_name': 'Islom', 'last_name': 'Sheraliyev', 'username': 'eLoving', 'language_code': 'en'}, 'chat': {'id': 1980653792, 'first_name': 'Islom', 'last_name': 'Sheraliyev', 'username': 'eLoving', 'type': 'private'}, 'date': 1711829912, 'text': '/start', 'entities': [{'offset': 0, 'length': 6, 'type': 'bot_command'}]}}
1980653792
Error creating user: no such table: referrals
{'content_type': 'text', 'id': 433, 'message_id': 433, 'from_user': {'id': 1980653792, 'is_bot': False, 'first_name': 'Islom', 'username': 'eLoving', 'last_name': 'Sheraliyev', 'language_code': 'en', 'can_join_groups': None, 'can_read_all_group_messages': None, 'supports_inline_queries': None, 'is_premium': None, 'added_to_attachment_menu': None}, 'date': 1711830012, 'chat': {'id': 1980653792, 'type': 'private', 'title': None, 'username': 'eLoving', 'first_name': 'Islom', 'last_name': 'Sheraliyev', 'is_forum': None, 'photo': None, 'bio': None, 'join_to_send_messages': None, 'join_by_request': None, 'has_private_forwards': None, 'has_restricted_voice_and_video_messages': None, 'description': None, 'invite_link': None, 'pinned_message': None, 'permissions': None, 'slow_mode_delay': None, 'message_auto_delete_time': None, 'has_protected_content': None, 'sticker_set_name': None, 'can_set_sticker_set': None, 'linked_chat_id': None, 'location': None, 'active_usernames': None, 'emoji_status_custom_emoji_id': None, 'has_hidden_members': None, 'has_aggressive_anti_spam_enabled': None, 'emoji_status_expiration_date': None, 'available_reactions': None, 'accent_color_id': None, 'background_custom_emoji_id': None, 'profile_accent_color_id': None, 'profile_background_custom_emoji_id': None, 'has_visible_history': None, 'unrestrict_boost_count': None, 'custom_emoji_sticker_set_name': None}, 'sender_chat': None, 'is_automatic_forward': None, 'reply_to_message': None, 'via_bot': None, 'edit_date': None, 'has_protected_content': None, 'media_group_id': None, 'author_signature': None, 'text': '/start', 'entities': [<telebot.types.MessageEntity object at 0x7fdb86cf2a90>], 'caption_entities': None, 'audio': None, 'document': None, 'photo': None, 'sticker': None, 'video': None, 'video_note': None, 'voice': None, 'caption': None, 'contact': None, 'location': None, 'venue': None, 'animation': None, 'dice': None, 'new_chat_members': None, 'left_chat_member': None, 'new_chat_title': None, 'new_chat_photo': None, 'delete_chat_photo': None, 'group_chat_created': None, 'supergroup_chat_created': None, 'channel_chat_created': None, 'migrate_to_chat_id': None, 'migrate_from_chat_id': None, 'pinned_message': None, 'invoice': None, 'successful_payment': None, 'connected_website': None, 'reply_markup': None, 'message_thread_id': None, 'is_topic_message': None, 'forum_topic_created': None, 'forum_topic_closed': None, 'forum_topic_reopened': None, 'has_media_spoiler': None, 'forum_topic_edited': None, 'general_forum_topic_hidden': None, 'general_forum_topic_unhidden': None, 'write_access_allowed': None, 'users_shared': None, 'chat_shared': None, 'story': None, 'external_reply': None, 'quote': None, 'link_preview_options': None, 'giveaway_created': None, 'giveaway': None, 'giveaway_winners': None, 'giveaway_completed': None, 'forward_origin': None, 'boost_added': None, 'sender_boost_count': None, 'reply_to_story': None, 'json': {'message_id': 433, 'from': {'id': 1980653792, 'is_bot': False, 'first_name': 'Islom', 'last_name': 'Sheraliyev', 'username': 'eLoving', 'language_code': 'en'}, 'chat': {'id': 1980653792, 'first_name': 'Islom', 'last_name': 'Sheraliyev', 'username': 'eLoving', 'type': 'private'}, 'date': 1711830012, 'text': '/start', 'entities': [{'offset': 0, 'length': 6, 'type': 'bot_command'}]}}
Error fetching refs count: no such table: referrals
Error checking if user is logged: no such table: referrals
Error incrementing referral count: no such table: referrals
6802165407
Error creating user: no such table: referrals
2024-03-31 17:28:10,264 (__init__.py:1147 MainThread) ERROR - TeleBot: "Threaded polling exception: A request to the Telegram API was unsuccessful. Error code: 502. Description: Bad Gateway"
2024-03-31 17:28:10,266 (__init__.py:1149 MainThread) ERROR - TeleBot: "Exception traceback:
Traceback (most recent call last):
  File "/home/sobirjonovmuhammadazizbek/course-bot/venv/lib/python3.11/site-packages/telebot/__init__.py", line 1140, in __threaded_polling
    polling_thread.raise_exceptions()
  File "/home/sobirjonovmuhammadazizbek/course-bot/venv/lib/python3.11/site-packages/telebot/util.py", line 110, in raise_exceptions
    raise self.exception_info
  File "/home/sobirjonovmuhammadazizbek/course-bot/venv/lib/python3.11/site-packages/telebot/util.py", line 92, in run
    task(*args, **kwargs)
  File "/home/sobirjonovmuhammadazizbek/course-bot/venv/lib/python3.11/site-packages/telebot/__init__.py", line 661, in __retrieve_updates
    updates = self.get_updates(offset=(self.last_update_id + 1),
             ^^^^^^^^^^^^^^^^^^^^^^^^^^^^^^^^^^^^^^^^^^^^^^^^^^^
  File "/home/sobirjonovmuhammadazizbek/course-bot/venv/lib/python3.11/site-packages/telebot/__init__.py", line 633, in get_updates
    json_updates = apihelper.get_updates(
                   ^^^^^^^^^^^^^^^^^^^^^^
  File "/home/sobirjonovmuhammadazizbek/course-bot/venv/lib/python3.11/site-packages/telebot/apihelper.py", line 321, in get_updates
    return _make_request(token, method_url, params=payload)
           ^^^^^^^^^^^^^^^^^^^^^^^^^^^^^^^^^^^^^^^^^^^^^^^^
  File "/home/sobirjonovmuhammadazizbek/course-bot/venv/lib/python3.11/site-packages/telebot/apihelper.py", line 164, in _make_request
    json_result = _check_result(method_name, result)
                  ^^^^^^^^^^^^^^^^^^^^^^^^^^^^^^^^^^
  File "/home/sobirjonovmuhammadazizbek/course-bot/venv/lib/python3.11/site-packages/telebot/apihelper.py", line 191, in _check_result
    raise ApiTelegramException(method_name, result, result_json)
telebot.apihelper.ApiTelegramException: A request to the Telegram API was unsuccessful. Error code: 502. Description: Bad Gateway
"
2024-03-31 17:28:10,664 (__init__.py:1147 MainThread) ERROR - TeleBot: "Threaded polling exception: A request to the Telegram API was unsuccessful. Error code: 502. Description: Bad Gateway"
2024-03-31 17:28:10,664 (__init__.py:1149 MainThread) ERROR - TeleBot: "Exception traceback:
Traceback (most recent call last):
  File "/home/sobirjonovmuhammadazizbek/course-bot/venv/lib/python3.11/site-packages/telebot/__init__.py", line 1140, in __threaded_polling
    polling_thread.raise_exceptions()
  File "/home/sobirjonovmuhammadazizbek/course-bot/venv/lib/python3.11/site-packages/telebot/util.py", line 110, in raise_exceptions
    raise self.exception_info
  File "/home/sobirjonovmuhammadazizbek/course-bot/venv/lib/python3.11/site-packages/telebot/util.py", line 92, in run
    task(*args, **kwargs)
  File "/home/sobirjonovmuhammadazizbek/course-bot/venv/lib/python3.11/site-packages/telebot/__init__.py", line 661, in __retrieve_updates
    updates = self.get_updates(offset=(self.last_update_id + 1),
             ^^^^^^^^^^^^^^^^^^^^^^^^^^^^^^^^^^^^^^^^^^^^^^^^^^^
  File "/home/sobirjonovmuhammadazizbek/course-bot/venv/lib/python3.11/site-packages/telebot/__init__.py", line 633, in get_updates
    json_updates = apihelper.get_updates(
                   ^^^^^^^^^^^^^^^^^^^^^^
  File "/home/sobirjonovmuhammadazizbek/course-bot/venv/lib/python3.11/site-packages/telebot/apihelper.py", line 321, in get_updates
    return _make_request(token, method_url, params=payload)
           ^^^^^^^^^^^^^^^^^^^^^^^^^^^^^^^^^^^^^^^^^^^^^^^^
  File "/home/sobirjonovmuhammadazizbek/course-bot/venv/lib/python3.11/site-packages/telebot/apihelper.py", line 164, in _make_request
    json_result = _check_result(method_name, result)
                  ^^^^^^^^^^^^^^^^^^^^^^^^^^^^^^^^^^
  File "/home/sobirjonovmuhammadazizbek/course-bot/venv/lib/python3.11/site-packages/telebot/apihelper.py", line 191, in _check_result
    raise ApiTelegramException(method_name, result, result_json)
telebot.apihelper.ApiTelegramException: A request to the Telegram API was unsuccessful. Error code: 502. Description: Bad Gateway
"
2024-03-31 17:28:11,324 (__init__.py:1147 MainThread) ERROR - TeleBot: "Threaded polling exception: A request to the Telegram API was unsuccessful. Error code: 502. Description: Bad Gateway"
2024-03-31 17:28:11,325 (__init__.py:1149 MainThread) ERROR - TeleBot: "Exception traceback:
Traceback (most recent call last):
  File "/home/sobirjonovmuhammadazizbek/course-bot/venv/lib/python3.11/site-packages/telebot/__init__.py", line 1140, in __threaded_polling
    polling_thread.raise_exceptions()
  File "/home/sobirjonovmuhammadazizbek/course-bot/venv/lib/python3.11/site-packages/telebot/util.py", line 110, in raise_exceptions
    raise self.exception_info
  File "/home/sobirjonovmuhammadazizbek/course-bot/venv/lib/python3.11/site-packages/telebot/util.py", line 92, in run
    task(*args, **kwargs)
  File "/home/sobirjonovmuhammadazizbek/course-bot/venv/lib/python3.11/site-packages/telebot/__init__.py", line 661, in __retrieve_updates
    updates = self.get_updates(offset=(self.last_update_id + 1),
             ^^^^^^^^^^^^^^^^^^^^^^^^^^^^^^^^^^^^^^^^^^^^^^^^^^^
  File "/home/sobirjonovmuhammadazizbek/course-bot/venv/lib/python3.11/site-packages/telebot/__init__.py", line 633, in get_updates
    json_updates = apihelper.get_updates(
                   ^^^^^^^^^^^^^^^^^^^^^^
  File "/home/sobirjonovmuhammadazizbek/course-bot/venv/lib/python3.11/site-packages/telebot/apihelper.py", line 321, in get_updates
    return _make_request(token, method_url, params=payload)
           ^^^^^^^^^^^^^^^^^^^^^^^^^^^^^^^^^^^^^^^^^^^^^^^^
  File "/home/sobirjonovmuhammadazizbek/course-bot/venv/lib/python3.11/site-packages/telebot/apihelper.py", line 164, in _make_request
    json_result = _check_result(method_name, result)
                  ^^^^^^^^^^^^^^^^^^^^^^^^^^^^^^^^^^
  File "/home/sobirjonovmuhammadazizbek/course-bot/venv/lib/python3.11/site-packages/telebot/apihelper.py", line 191, in _check_result
    raise ApiTelegramException(method_name, result, result_json)
telebot.apihelper.ApiTelegramException: A request to the Telegram API was unsuccessful. Error code: 502. Description: Bad Gateway
"
2024-03-31 17:28:12,471 (__init__.py:1147 MainThread) ERROR - TeleBot: "Threaded polling exception: A request to the Telegram API was unsuccessful. Error code: 502. Description: Bad Gateway"
2024-03-31 17:28:12,472 (__init__.py:1149 MainThread) ERROR - TeleBot: "Exception traceback:
Traceback (most recent call last):
  File "/home/sobirjonovmuhammadazizbek/course-bot/venv/lib/python3.11/site-packages/telebot/__init__.py", line 1140, in __threaded_polling
    polling_thread.raise_exceptions()
  File "/home/sobirjonovmuhammadazizbek/course-bot/venv/lib/python3.11/site-packages/telebot/util.py", line 110, in raise_exceptions
    raise self.exception_info
  File "/home/sobirjonovmuhammadazizbek/course-bot/venv/lib/python3.11/site-packages/telebot/util.py", line 92, in run
    task(*args, **kwargs)
  File "/home/sobirjonovmuhammadazizbek/course-bot/venv/lib/python3.11/site-packages/telebot/__init__.py", line 661, in __retrieve_updates
    updates = self.get_updates(offset=(self.last_update_id + 1),
             ^^^^^^^^^^^^^^^^^^^^^^^^^^^^^^^^^^^^^^^^^^^^^^^^^^^
  File "/home/sobirjonovmuhammadazizbek/course-bot/venv/lib/python3.11/site-packages/telebot/__init__.py", line 633, in get_updates
    json_updates = apihelper.get_updates(
                   ^^^^^^^^^^^^^^^^^^^^^^
  File "/home/sobirjonovmuhammadazizbek/course-bot/venv/lib/python3.11/site-packages/telebot/apihelper.py", line 321, in get_updates
    return _make_request(token, method_url, params=payload)
           ^^^^^^^^^^^^^^^^^^^^^^^^^^^^^^^^^^^^^^^^^^^^^^^^
  File "/home/sobirjonovmuhammadazizbek/course-bot/venv/lib/python3.11/site-packages/telebot/apihelper.py", line 164, in _make_request
    json_result = _check_result(method_name, result)
                  ^^^^^^^^^^^^^^^^^^^^^^^^^^^^^^^^^^
  File "/home/sobirjonovmuhammadazizbek/course-bot/venv/lib/python3.11/site-packages/telebot/apihelper.py", line 191, in _check_result
    raise ApiTelegramException(method_name, result, result_json)
telebot.apihelper.ApiTelegramException: A request to the Telegram API was unsuccessful. Error code: 502. Description: Bad Gateway
"
{'content_type': 'text', 'id': 447, 'message_id': 447, 'from_user': {'id': 6802165407, 'is_bot': False, 'first_name': 'Islom', 'username': 'isheraliyev', 'last_name': None, 'language_code': 'en', 'can_join_groups': None, 'can_read_all_group_messages': None, 'supports_inline_queries': None, 'is_premium': None, 'added_to_attachment_menu': None}, 'date': 1711830139, 'chat': {'id': 6802165407, 'type': 'private', 'title': None, 'username': 'isheraliyev', 'first_name': 'Islom', 'last_name': None, 'is_forum': None, 'photo': None, 'bio': None, 'join_to_send_messages': None, 'join_by_request': None, 'has_private_forwards': None, 'has_restricted_voice_and_video_messages': None, 'description': None, 'invite_link': None, 'pinned_message': None, 'permissions': None, 'slow_mode_delay': None, 'message_auto_delete_time': None, 'has_protected_content': None, 'sticker_set_name': None, 'can_set_sticker_set': None, 'linked_chat_id': None, 'location': None, 'active_usernames': None, 'emoji_status_custom_emoji_id': None, 'has_hidden_members': None, 'has_aggressive_anti_spam_enabled': None, 'emoji_status_expiration_date': None, 'available_reactions': None, 'accent_color_id': None, 'background_custom_emoji_id': None, 'profile_accent_color_id': None, 'profile_background_custom_emoji_id': None, 'has_visible_history': None, 'unrestrict_boost_count': None, 'custom_emoji_sticker_set_name': None}, 'sender_chat': None, 'is_automatic_forward': None, 'reply_to_message': None, 'via_bot': None, 'edit_date': None, 'has_protected_content': None, 'media_group_id': None, 'author_signature': None, 'text': '/start 1980653792', 'entities': [<telebot.types.MessageEntity object at 0x7fdb86cf57d0>], 'caption_entities': None, 'audio': None, 'document': None, 'photo': None, 'sticker': None, 'video': None, 'video_note': None, 'voice': None, 'caption': None, 'contact': None, 'location': None, 'venue': None, 'animation': None, 'dice': None, 'new_chat_members': None, 'left_chat_member': None, 'new_chat_title': None, 'new_chat_photo': None, 'delete_chat_photo': None, 'group_chat_created': None, 'supergroup_chat_created': None, 'channel_chat_created': None, 'migrate_to_chat_id': None, 'migrate_from_chat_id': None, 'pinned_message': None, 'invoice': None, 'successful_payment': None, 'connected_website': None, 'reply_markup': None, 'message_thread_id': None, 'is_topic_message': None, 'forum_topic_created': None, 'forum_topic_closed': None, 'forum_topic_reopened': None, 'has_media_spoiler': None, 'forum_topic_edited': None, 'general_forum_topic_hidden': None, 'general_forum_topic_unhidden': None, 'write_access_allowed': None, 'users_shared': None, 'chat_shared': None, 'story': None, 'external_reply': None, 'quote': None, 'link_preview_options': None, 'giveaway_created': None, 'giveaway': None, 'giveaway_winners': None, 'giveaway_completed': None, 'forward_origin': None, 'boost_added': None, 'sender_boost_count': None, 'reply_to_story': None, 'json': {'message_id': 447, 'from': {'id': 6802165407, 'is_bot': False, 'first_name': 'Islom', 'username': 'isheraliyev', 'language_code': 'en'}, 'chat': {'id': 6802165407, 'first_name': 'Islom', 'username': 'isheraliyev', 'type': 'private'}, 'date': 1711830139, 'text': '/start 1980653792', 'entities': [{'offset': 0, 'length': 6, 'type': 'bot_command'}]}}
Error fetching refs count: no such table: referrals
Error incrementing referral count: no such table: referrals
Error fetching refs count: no such table: referrals
Traceback (most recent call last):
  File "/home/sobirjonovmuhammadazizbek/course-bot/venv/lib/python3.11/site-packages/urllib3/connectionpool.py", line 537, in _make_request
    response = conn.getresponse()
               ^^^^^^^^^^^^^^^^^^
  File "/home/sobirjonovmuhammadazizbek/course-bot/venv/lib/python3.11/site-packages/urllib3/connection.py", line 466, in getresponse
    httplib_response = super().getresponse()
                       ^^^^^^^^^^^^^^^^^^^^^
  File "/usr/lib/python3.11/http/client.py", line 1374, in getresponse
    response.begin()
  File "/usr/lib/python3.11/http/client.py", line 318, in begin
    version, status, reason = self._read_status()
                              ^^^^^^^^^^^^^^^^^^^
  File "/usr/lib/python3.11/http/client.py", line 279, in _read_status
    line = str(self.fp.readline(_MAXLINE + 1), "iso-8859-1")
               ^^^^^^^^^^^^^^^^^^^^^^^^^^^^^^
  File "/usr/lib/python3.11/socket.py", line 706, in readinto
    return self._sock.recv_into(b)
           ^^^^^^^^^^^^^^^^^^^^^^^
  File "/usr/lib/python3.11/ssl.py", line 1278, in recv_into
    return self.read(nbytes, buffer)
           ^^^^^^^^^^^^^^^^^^^^^^^^^
  File "/usr/lib/python3.11/ssl.py", line 1134, in read
    return self._sslobj.read(len, buffer)
           ^^^^^^^^^^^^^^^^^^^^^^^^^^^^^^
TimeoutError: The read operation timed out

The above exception was the direct cause of the following exception:

Traceback (most recent call last):
  File "/home/sobirjonovmuhammadazizbek/course-bot/venv/lib/python3.11/site-packages/requests/adapters.py", line 486, in send
    resp = conn.urlopen(
           ^^^^^^^^^^^^^
  File "/home/sobirjonovmuhammadazizbek/course-bot/venv/lib/python3.11/site-packages/urllib3/connectionpool.py", line 847, in urlopen
    retries = retries.increment(
              ^^^^^^^^^^^^^^^^^^
  File "/home/sobirjonovmuhammadazizbek/course-bot/venv/lib/python3.11/site-packages/urllib3/util/retry.py", line 470, in increment
    raise reraise(type(error), error, _stacktrace)
          ^^^^^^^^^^^^^^^^^^^^^^^^^^^^^^^^^^^^^^^^
  File "/home/sobirjonovmuhammadazizbek/course-bot/venv/lib/python3.11/site-packages/urllib3/util/util.py", line 39, in reraise
    raise value
  File "/home/sobirjonovmuhammadazizbek/course-bot/venv/lib/python3.11/site-packages/urllib3/connectionpool.py", line 793, in urlopen
    response = self._make_request(
               ^^^^^^^^^^^^^^^^^^^
  File "/home/sobirjonovmuhammadazizbek/course-bot/venv/lib/python3.11/site-packages/urllib3/connectionpool.py", line 539, in _make_request
    self._raise_timeout(err=e, url=url, timeout_value=read_timeout)
  File "/home/sobirjonovmuhammadazizbek/course-bot/venv/lib/python3.11/site-packages/urllib3/connectionpool.py", line 370, in _raise_timeout
    raise ReadTimeoutError(
urllib3.exceptions.ReadTimeoutError: HTTPSConnectionPool(host='api.telegram.org', port=443): Read timed out. (read timeout=25)

During handling of the above exception, another exception occurred:

Traceback (most recent call last):
  File "/home/sobirjonovmuhammadazizbek/course-bot/bot.py", line 159, in <module>
    bot.run()
  File "/home/sobirjonovmuhammadazizbek/course-bot/bot.py", line 154, in run
    self.bot.polling(none_stop=True)
  File "/home/sobirjonovmuhammadazizbek/course-bot/venv/lib/python3.11/site-packages/telebot/__init__.py", line 1104, in polling
    self.__threaded_polling(non_stop=non_stop, interval=interval, timeout=timeout, long_polling_timeout=long_polling_timeout,
  File "/home/sobirjonovmuhammadazizbek/course-bot/venv/lib/python3.11/site-packages/telebot/__init__.py", line 1179, in __threaded_polling
    raise e
  File "/home/sobirjonovmuhammadazizbek/course-bot/venv/lib/python3.11/site-packages/telebot/__init__.py", line 1140, in __threaded_polling
    polling_thread.raise_exceptions()
  File "/home/sobirjonovmuhammadazizbek/course-bot/venv/lib/python3.11/site-packages/telebot/util.py", line 110, in raise_exceptions
    raise self.exception_info
  File "/home/sobirjonovmuhammadazizbek/course-bot/venv/lib/python3.11/site-packages/telebot/util.py", line 92, in run
    task(*args, **kwargs)
  File "/home/sobirjonovmuhammadazizbek/course-bot/venv/lib/python3.11/site-packages/telebot/__init__.py", line 661, in __retrieve_updates
    updates = self.get_updates(offset=(self.last_update_id + 1), 
              ^^^^^^^^^^^^^^^^^^^^^^^^^^^^^^^^^^^^^^^^^^^^^^^^^^
  File "/home/sobirjonovmuhammadazizbek/course-bot/venv/lib/python3.11/site-packages/telebot/__init__.py", line 633, in get_updates
    json_updates = apihelper.get_updates(
                   ^^^^^^^^^^^^^^^^^^^^^^
  File "/home/sobirjonovmuhammadazizbek/course-bot/venv/lib/python3.11/site-packages/telebot/apihelper.py", line 321, in get_updates
    return _make_request(token, method_url, params=payload)
           ^^^^^^^^^^^^^^^^^^^^^^^^^^^^^^^^^^^^^^^^^^^^^^^^
  File "/home/sobirjonovmuhammadazizbek/course-bot/venv/lib/python3.11/site-packages/telebot/apihelper.py", line 158, in _make_request
    result = _get_req_session().request(
             ^^^^^^^^^^^^^^^^^^^^^^^^^^^
  File "/home/sobirjonovmuhammadazizbek/course-bot/venv/lib/python3.11/site-packages/requests/sessions.py", line 589, in request
    resp = self.send(prep, **send_kwargs)
           ^^^^^^^^^^^^^^^^^^^^^^^^^^^^^^
  File "/home/sobirjonovmuhammadazizbek/course-bot/venv/lib/python3.11/site-packages/requests/sessions.py", line 703, in send
    r = adapter.send(request, **kwargs)
        ^^^^^^^^^^^^^^^^^^^^^^^^^^^^^^^
  File "/home/sobirjonovmuhammadazizbek/course-bot/venv/lib/python3.11/site-packages/requests/adapters.py", line 532, in send
    raise ReadTimeout(e, request=request)
requests.exceptions.ReadTimeout: HTTPSConnectionPool(host='api.telegram.org', port=443): Read timed out. (read timeout=25)
Traceback (most recent call last):
  File "/home/sobirjonovmuhammadazizbek/course-bot/bot.py", line 1, in <module>
    from telebot import TeleBot
ModuleNotFoundError: No module named 'telebot'
Traceback (most recent call last):
  File "/home/sobirjonovmuhammadazizbek/course-bot/bot.py", line 1, in <module>
    from telebot import TeleBot
ModuleNotFoundError: No module named 'telebot'
Traceback (most recent call last):
  File "/home/sobirjonovmuhammadazizbek/course-bot/bot.py", line 1, in <module>
    from telebot import TeleBot
ModuleNotFoundError: No module named 'telebot'
Traceback (most recent call last):
  File "/home/sobirjonovmuhammadazizbek/course-bot/bot.py", line 1, in <module>
    from telebot import TeleBot
ModuleNotFoundError: No module named 'telebot'
2024-04-02 07:48:55,004 (__init__.py:1147 MainThread) ERROR - TeleBot: "Threaded polling exception: A request to the Telegram API was unsuccessful. Error code: 409. Description: Conflict: terminated by other getUpdates request; make sure that only one bot instance is running"
2024-04-02 07:48:55,005 (__init__.py:1149 MainThread) ERROR - TeleBot: "Exception traceback:
Traceback (most recent call last):
  File "/home/sobirjonovmuhammadazizbek/course-bot/venv/lib/python3.11/site-packages/telebot/__init__.py", line 1140, in __threaded_polling
    polling_thread.raise_exceptions()
  File "/home/sobirjonovmuhammadazizbek/course-bot/venv/lib/python3.11/site-packages/telebot/util.py", line 110, in raise_exceptions
    raise self.exception_info
  File "/home/sobirjonovmuhammadazizbek/course-bot/venv/lib/python3.11/site-packages/telebot/util.py", line 92, in run
    task(*args, **kwargs)
  File "/home/sobirjonovmuhammadazizbek/course-bot/venv/lib/python3.11/site-packages/telebot/__init__.py", line 661, in __retrieve_updates
    updates = self.get_updates(offset=(self.last_update_id + 1),
             ^^^^^^^^^^^^^^^^^^^^^^^^^^^^^^^^^^^^^^^^^^^^^^^^^^^
  File "/home/sobirjonovmuhammadazizbek/course-bot/venv/lib/python3.11/site-packages/telebot/__init__.py", line 633, in get_updates
    json_updates = apihelper.get_updates(
                   ^^^^^^^^^^^^^^^^^^^^^^
  File "/home/sobirjonovmuhammadazizbek/course-bot/venv/lib/python3.11/site-packages/telebot/apihelper.py", line 321, in get_updates
    return _make_request(token, method_url, params=payload)
           ^^^^^^^^^^^^^^^^^^^^^^^^^^^^^^^^^^^^^^^^^^^^^^^^
  File "/home/sobirjonovmuhammadazizbek/course-bot/venv/lib/python3.11/site-packages/telebot/apihelper.py", line 164, in _make_request
    json_result = _check_result(method_name, result)
                  ^^^^^^^^^^^^^^^^^^^^^^^^^^^^^^^^^^
  File "/home/sobirjonovmuhammadazizbek/course-bot/venv/lib/python3.11/site-packages/telebot/apihelper.py", line 191, in _check_result
    raise ApiTelegramException(method_name, result, result_json)
telebot.apihelper.ApiTelegramException: A request to the Telegram API was unsuccessful. Error code: 409. Description: Conflict: terminated by other getUpdates request; make sure that only one bot instance is running
"
2024-04-02 07:48:58,407 (__init__.py:1147 MainThread) ERROR - TeleBot: "Threaded polling exception: A request to the Telegram API was unsuccessful. Error code: 409. Description: Conflict: terminated by other getUpdates request; make sure that only one bot instance is running"
2024-04-02 07:48:58,408 (__init__.py:1149 MainThread) ERROR - TeleBot: "Exception traceback:
Traceback (most recent call last):
  File "/home/sobirjonovmuhammadazizbek/course-bot/venv/lib/python3.11/site-packages/telebot/__init__.py", line 1140, in __threaded_polling
    polling_thread.raise_exceptions()
  File "/home/sobirjonovmuhammadazizbek/course-bot/venv/lib/python3.11/site-packages/telebot/util.py", line 110, in raise_exceptions
    raise self.exception_info
  File "/home/sobirjonovmuhammadazizbek/course-bot/venv/lib/python3.11/site-packages/telebot/util.py", line 92, in run
    task(*args, **kwargs)
  File "/home/sobirjonovmuhammadazizbek/course-bot/venv/lib/python3.11/site-packages/telebot/__init__.py", line 661, in __retrieve_updates
    updates = self.get_updates(offset=(self.last_update_id + 1),
             ^^^^^^^^^^^^^^^^^^^^^^^^^^^^^^^^^^^^^^^^^^^^^^^^^^^
  File "/home/sobirjonovmuhammadazizbek/course-bot/venv/lib/python3.11/site-packages/telebot/__init__.py", line 633, in get_updates
    json_updates = apihelper.get_updates(
                   ^^^^^^^^^^^^^^^^^^^^^^
  File "/home/sobirjonovmuhammadazizbek/course-bot/venv/lib/python3.11/site-packages/telebot/apihelper.py", line 321, in get_updates
    return _make_request(token, method_url, params=payload)
           ^^^^^^^^^^^^^^^^^^^^^^^^^^^^^^^^^^^^^^^^^^^^^^^^
  File "/home/sobirjonovmuhammadazizbek/course-bot/venv/lib/python3.11/site-packages/telebot/apihelper.py", line 164, in _make_request
    json_result = _check_result(method_name, result)
                  ^^^^^^^^^^^^^^^^^^^^^^^^^^^^^^^^^^
  File "/home/sobirjonovmuhammadazizbek/course-bot/venv/lib/python3.11/site-packages/telebot/apihelper.py", line 191, in _check_result
    raise ApiTelegramException(method_name, result, result_json)
telebot.apihelper.ApiTelegramException: A request to the Telegram API was unsuccessful. Error code: 409. Description: Conflict: terminated by other getUpdates request; make sure that only one bot instance is running
"
2024-04-02 07:48:58,809 (__init__.py:1147 MainThread) ERROR - TeleBot: "Threaded polling exception: A request to the Telegram API was unsuccessful. Error code: 409. Description: Conflict: terminated by other getUpdates request; make sure that only one bot instance is running"
2024-04-02 07:48:58,810 (__init__.py:1149 MainThread) ERROR - TeleBot: "Exception traceback:
Traceback (most recent call last):
  File "/home/sobirjonovmuhammadazizbek/course-bot/venv/lib/python3.11/site-packages/telebot/__init__.py", line 1140, in __threaded_polling
    polling_thread.raise_exceptions()
  File "/home/sobirjonovmuhammadazizbek/course-bot/venv/lib/python3.11/site-packages/telebot/util.py", line 110, in raise_exceptions
    raise self.exception_info
  File "/home/sobirjonovmuhammadazizbek/course-bot/venv/lib/python3.11/site-packages/telebot/util.py", line 92, in run
    task(*args, **kwargs)
  File "/home/sobirjonovmuhammadazizbek/course-bot/venv/lib/python3.11/site-packages/telebot/__init__.py", line 661, in __retrieve_updates
    updates = self.get_updates(offset=(self.last_update_id + 1),
             ^^^^^^^^^^^^^^^^^^^^^^^^^^^^^^^^^^^^^^^^^^^^^^^^^^^
  File "/home/sobirjonovmuhammadazizbek/course-bot/venv/lib/python3.11/site-packages/telebot/__init__.py", line 633, in get_updates
    json_updates = apihelper.get_updates(
                   ^^^^^^^^^^^^^^^^^^^^^^
  File "/home/sobirjonovmuhammadazizbek/course-bot/venv/lib/python3.11/site-packages/telebot/apihelper.py", line 321, in get_updates
    return _make_request(token, method_url, params=payload)
           ^^^^^^^^^^^^^^^^^^^^^^^^^^^^^^^^^^^^^^^^^^^^^^^^
  File "/home/sobirjonovmuhammadazizbek/course-bot/venv/lib/python3.11/site-packages/telebot/apihelper.py", line 164, in _make_request
    json_result = _check_result(method_name, result)
                  ^^^^^^^^^^^^^^^^^^^^^^^^^^^^^^^^^^
  File "/home/sobirjonovmuhammadazizbek/course-bot/venv/lib/python3.11/site-packages/telebot/apihelper.py", line 191, in _check_result
    raise ApiTelegramException(method_name, result, result_json)
telebot.apihelper.ApiTelegramException: A request to the Telegram API was unsuccessful. Error code: 409. Description: Conflict: terminated by other getUpdates request; make sure that only one bot instance is running
"
2024-04-02 07:49:02,492 (__init__.py:1147 MainThread) ERROR - TeleBot: "Threaded polling exception: A request to the Telegram API was unsuccessful. Error code: 409. Description: Conflict: terminated by other getUpdates request; make sure that only one bot instance is running"
2024-04-02 07:49:02,493 (__init__.py:1149 MainThread) ERROR - TeleBot: "Exception traceback:
Traceback (most recent call last):
  File "/home/sobirjonovmuhammadazizbek/course-bot/venv/lib/python3.11/site-packages/telebot/__init__.py", line 1140, in __threaded_polling
    polling_thread.raise_exceptions()
  File "/home/sobirjonovmuhammadazizbek/course-bot/venv/lib/python3.11/site-packages/telebot/util.py", line 110, in raise_exceptions
    raise self.exception_info
  File "/home/sobirjonovmuhammadazizbek/course-bot/venv/lib/python3.11/site-packages/telebot/util.py", line 92, in run
    task(*args, **kwargs)
  File "/home/sobirjonovmuhammadazizbek/course-bot/venv/lib/python3.11/site-packages/telebot/__init__.py", line 661, in __retrieve_updates
    updates = self.get_updates(offset=(self.last_update_id + 1),
             ^^^^^^^^^^^^^^^^^^^^^^^^^^^^^^^^^^^^^^^^^^^^^^^^^^^
  File "/home/sobirjonovmuhammadazizbek/course-bot/venv/lib/python3.11/site-packages/telebot/__init__.py", line 633, in get_updates
    json_updates = apihelper.get_updates(
                   ^^^^^^^^^^^^^^^^^^^^^^
  File "/home/sobirjonovmuhammadazizbek/course-bot/venv/lib/python3.11/site-packages/telebot/apihelper.py", line 321, in get_updates
    return _make_request(token, method_url, params=payload)
           ^^^^^^^^^^^^^^^^^^^^^^^^^^^^^^^^^^^^^^^^^^^^^^^^
  File "/home/sobirjonovmuhammadazizbek/course-bot/venv/lib/python3.11/site-packages/telebot/apihelper.py", line 164, in _make_request
    json_result = _check_result(method_name, result)
                  ^^^^^^^^^^^^^^^^^^^^^^^^^^^^^^^^^^
  File "/home/sobirjonovmuhammadazizbek/course-bot/venv/lib/python3.11/site-packages/telebot/apihelper.py", line 191, in _check_result
    raise ApiTelegramException(method_name, result, result_json)
telebot.apihelper.ApiTelegramException: A request to the Telegram API was unsuccessful. Error code: 409. Description: Conflict: terminated by other getUpdates request; make sure that only one bot instance is running
"
2024-04-02 07:49:03,138 (__init__.py:1147 MainThread) ERROR - TeleBot: "Threaded polling exception: A request to the Telegram API was unsuccessful. Error code: 409. Description: Conflict: terminated by other getUpdates request; make sure that only one bot instance is running"
2024-04-02 07:49:03,139 (__init__.py:1149 MainThread) ERROR - TeleBot: "Exception traceback:
Traceback (most recent call last):
  File "/home/sobirjonovmuhammadazizbek/course-bot/venv/lib/python3.11/site-packages/telebot/__init__.py", line 1140, in __threaded_polling
    polling_thread.raise_exceptions()
  File "/home/sobirjonovmuhammadazizbek/course-bot/venv/lib/python3.11/site-packages/telebot/util.py", line 110, in raise_exceptions
    raise self.exception_info
  File "/home/sobirjonovmuhammadazizbek/course-bot/venv/lib/python3.11/site-packages/telebot/util.py", line 92, in run
    task(*args, **kwargs)
  File "/home/sobirjonovmuhammadazizbek/course-bot/venv/lib/python3.11/site-packages/telebot/__init__.py", line 661, in __retrieve_updates
    updates = self.get_updates(offset=(self.last_update_id + 1),
             ^^^^^^^^^^^^^^^^^^^^^^^^^^^^^^^^^^^^^^^^^^^^^^^^^^^
  File "/home/sobirjonovmuhammadazizbek/course-bot/venv/lib/python3.11/site-packages/telebot/__init__.py", line 633, in get_updates
    json_updates = apihelper.get_updates(
                   ^^^^^^^^^^^^^^^^^^^^^^
  File "/home/sobirjonovmuhammadazizbek/course-bot/venv/lib/python3.11/site-packages/telebot/apihelper.py", line 321, in get_updates
    return _make_request(token, method_url, params=payload)
           ^^^^^^^^^^^^^^^^^^^^^^^^^^^^^^^^^^^^^^^^^^^^^^^^
  File "/home/sobirjonovmuhammadazizbek/course-bot/venv/lib/python3.11/site-packages/telebot/apihelper.py", line 164, in _make_request
    json_result = _check_result(method_name, result)
                  ^^^^^^^^^^^^^^^^^^^^^^^^^^^^^^^^^^
  File "/home/sobirjonovmuhammadazizbek/course-bot/venv/lib/python3.11/site-packages/telebot/apihelper.py", line 191, in _check_result
    raise ApiTelegramException(method_name, result, result_json)
telebot.apihelper.ApiTelegramException: A request to the Telegram API was unsuccessful. Error code: 409. Description: Conflict: terminated by other getUpdates request; make sure that only one bot instance is running
"
2024-04-02 07:49:07,284 (__init__.py:1147 MainThread) ERROR - TeleBot: "Threaded polling exception: A request to the Telegram API was unsuccessful. Error code: 409. Description: Conflict: terminated by other getUpdates request; make sure that only one bot instance is running"
2024-04-02 07:49:07,285 (__init__.py:1149 MainThread) ERROR - TeleBot: "Exception traceback:
Traceback (most recent call last):
  File "/home/sobirjonovmuhammadazizbek/course-bot/venv/lib/python3.11/site-packages/telebot/__init__.py", line 1140, in __threaded_polling
    polling_thread.raise_exceptions()
  File "/home/sobirjonovmuhammadazizbek/course-bot/venv/lib/python3.11/site-packages/telebot/util.py", line 110, in raise_exceptions
    raise self.exception_info
  File "/home/sobirjonovmuhammadazizbek/course-bot/venv/lib/python3.11/site-packages/telebot/util.py", line 92, in run
    task(*args, **kwargs)
  File "/home/sobirjonovmuhammadazizbek/course-bot/venv/lib/python3.11/site-packages/telebot/__init__.py", line 661, in __retrieve_updates
    updates = self.get_updates(offset=(self.last_update_id + 1),
             ^^^^^^^^^^^^^^^^^^^^^^^^^^^^^^^^^^^^^^^^^^^^^^^^^^^
  File "/home/sobirjonovmuhammadazizbek/course-bot/venv/lib/python3.11/site-packages/telebot/__init__.py", line 633, in get_updates
    json_updates = apihelper.get_updates(
                   ^^^^^^^^^^^^^^^^^^^^^^
  File "/home/sobirjonovmuhammadazizbek/course-bot/venv/lib/python3.11/site-packages/telebot/apihelper.py", line 321, in get_updates
    return _make_request(token, method_url, params=payload)
           ^^^^^^^^^^^^^^^^^^^^^^^^^^^^^^^^^^^^^^^^^^^^^^^^
  File "/home/sobirjonovmuhammadazizbek/course-bot/venv/lib/python3.11/site-packages/telebot/apihelper.py", line 164, in _make_request
    json_result = _check_result(method_name, result)
                  ^^^^^^^^^^^^^^^^^^^^^^^^^^^^^^^^^^
  File "/home/sobirjonovmuhammadazizbek/course-bot/venv/lib/python3.11/site-packages/telebot/apihelper.py", line 191, in _check_result
    raise ApiTelegramException(method_name, result, result_json)
telebot.apihelper.ApiTelegramException: A request to the Telegram API was unsuccessful. Error code: 409. Description: Conflict: terminated by other getUpdates request; make sure that only one bot instance is running
"
2024-04-02 07:49:08,432 (__init__.py:1147 MainThread) ERROR - TeleBot: "Threaded polling exception: A request to the Telegram API was unsuccessful. Error code: 409. Description: Conflict: terminated by other getUpdates request; make sure that only one bot instance is running"
2024-04-02 07:49:08,433 (__init__.py:1149 MainThread) ERROR - TeleBot: "Exception traceback:
Traceback (most recent call last):
  File "/home/sobirjonovmuhammadazizbek/course-bot/venv/lib/python3.11/site-packages/telebot/__init__.py", line 1140, in __threaded_polling
    polling_thread.raise_exceptions()
  File "/home/sobirjonovmuhammadazizbek/course-bot/venv/lib/python3.11/site-packages/telebot/util.py", line 110, in raise_exceptions
    raise self.exception_info
  File "/home/sobirjonovmuhammadazizbek/course-bot/venv/lib/python3.11/site-packages/telebot/util.py", line 92, in run
    task(*args, **kwargs)
  File "/home/sobirjonovmuhammadazizbek/course-bot/venv/lib/python3.11/site-packages/telebot/__init__.py", line 661, in __retrieve_updates
    updates = self.get_updates(offset=(self.last_update_id + 1),
             ^^^^^^^^^^^^^^^^^^^^^^^^^^^^^^^^^^^^^^^^^^^^^^^^^^^
  File "/home/sobirjonovmuhammadazizbek/course-bot/venv/lib/python3.11/site-packages/telebot/__init__.py", line 633, in get_updates
    json_updates = apihelper.get_updates(
                   ^^^^^^^^^^^^^^^^^^^^^^
  File "/home/sobirjonovmuhammadazizbek/course-bot/venv/lib/python3.11/site-packages/telebot/apihelper.py", line 321, in get_updates
    return _make_request(token, method_url, params=payload)
           ^^^^^^^^^^^^^^^^^^^^^^^^^^^^^^^^^^^^^^^^^^^^^^^^
  File "/home/sobirjonovmuhammadazizbek/course-bot/venv/lib/python3.11/site-packages/telebot/apihelper.py", line 164, in _make_request
    json_result = _check_result(method_name, result)
                  ^^^^^^^^^^^^^^^^^^^^^^^^^^^^^^^^^^
  File "/home/sobirjonovmuhammadazizbek/course-bot/venv/lib/python3.11/site-packages/telebot/apihelper.py", line 191, in _check_result
    raise ApiTelegramException(method_name, result, result_json)
telebot.apihelper.ApiTelegramException: A request to the Telegram API was unsuccessful. Error code: 409. Description: Conflict: terminated by other getUpdates request; make sure that only one bot instance is running
"
2024-04-02 07:49:13,578 (__init__.py:1147 MainThread) ERROR - TeleBot: "Threaded polling exception: A request to the Telegram API was unsuccessful. Error code: 409. Description: Conflict: terminated by other getUpdates request; make sure that only one bot instance is running"
2024-04-02 07:49:13,579 (__init__.py:1149 MainThread) ERROR - TeleBot: "Exception traceback:
Traceback (most recent call last):
  File "/home/sobirjonovmuhammadazizbek/course-bot/venv/lib/python3.11/site-packages/telebot/__init__.py", line 1140, in __threaded_polling
    polling_thread.raise_exceptions()
  File "/home/sobirjonovmuhammadazizbek/course-bot/venv/lib/python3.11/site-packages/telebot/util.py", line 110, in raise_exceptions
    raise self.exception_info
  File "/home/sobirjonovmuhammadazizbek/course-bot/venv/lib/python3.11/site-packages/telebot/util.py", line 92, in run
    task(*args, **kwargs)
  File "/home/sobirjonovmuhammadazizbek/course-bot/venv/lib/python3.11/site-packages/telebot/__init__.py", line 661, in __retrieve_updates
    updates = self.get_updates(offset=(self.last_update_id + 1),
             ^^^^^^^^^^^^^^^^^^^^^^^^^^^^^^^^^^^^^^^^^^^^^^^^^^^
  File "/home/sobirjonovmuhammadazizbek/course-bot/venv/lib/python3.11/site-packages/telebot/__init__.py", line 633, in get_updates
    json_updates = apihelper.get_updates(
                   ^^^^^^^^^^^^^^^^^^^^^^
  File "/home/sobirjonovmuhammadazizbek/course-bot/venv/lib/python3.11/site-packages/telebot/apihelper.py", line 321, in get_updates
    return _make_request(token, method_url, params=payload)
           ^^^^^^^^^^^^^^^^^^^^^^^^^^^^^^^^^^^^^^^^^^^^^^^^
  File "/home/sobirjonovmuhammadazizbek/course-bot/venv/lib/python3.11/site-packages/telebot/apihelper.py", line 164, in _make_request
    json_result = _check_result(method_name, result)
                  ^^^^^^^^^^^^^^^^^^^^^^^^^^^^^^^^^^
  File "/home/sobirjonovmuhammadazizbek/course-bot/venv/lib/python3.11/site-packages/telebot/apihelper.py", line 191, in _check_result
    raise ApiTelegramException(method_name, result, result_json)
telebot.apihelper.ApiTelegramException: A request to the Telegram API was unsuccessful. Error code: 409. Description: Conflict: terminated by other getUpdates request; make sure that only one bot instance is running
"
2024-04-02 07:49:15,723 (__init__.py:1147 MainThread) ERROR - TeleBot: "Threaded polling exception: A request to the Telegram API was unsuccessful. Error code: 409. Description: Conflict: terminated by other getUpdates request; make sure that only one bot instance is running"
2024-04-02 07:49:15,724 (__init__.py:1149 MainThread) ERROR - TeleBot: "Exception traceback:
Traceback (most recent call last):
  File "/home/sobirjonovmuhammadazizbek/course-bot/venv/lib/python3.11/site-packages/telebot/__init__.py", line 1140, in __threaded_polling
    polling_thread.raise_exceptions()
  File "/home/sobirjonovmuhammadazizbek/course-bot/venv/lib/python3.11/site-packages/telebot/util.py", line 110, in raise_exceptions
    raise self.exception_info
  File "/home/sobirjonovmuhammadazizbek/course-bot/venv/lib/python3.11/site-packages/telebot/util.py", line 92, in run
    task(*args, **kwargs)
  File "/home/sobirjonovmuhammadazizbek/course-bot/venv/lib/python3.11/site-packages/telebot/__init__.py", line 661, in __retrieve_updates
    updates = self.get_updates(offset=(self.last_update_id + 1),
             ^^^^^^^^^^^^^^^^^^^^^^^^^^^^^^^^^^^^^^^^^^^^^^^^^^^
  File "/home/sobirjonovmuhammadazizbek/course-bot/venv/lib/python3.11/site-packages/telebot/__init__.py", line 633, in get_updates
    json_updates = apihelper.get_updates(
                   ^^^^^^^^^^^^^^^^^^^^^^
  File "/home/sobirjonovmuhammadazizbek/course-bot/venv/lib/python3.11/site-packages/telebot/apihelper.py", line 321, in get_updates
    return _make_request(token, method_url, params=payload)
           ^^^^^^^^^^^^^^^^^^^^^^^^^^^^^^^^^^^^^^^^^^^^^^^^
  File "/home/sobirjonovmuhammadazizbek/course-bot/venv/lib/python3.11/site-packages/telebot/apihelper.py", line 164, in _make_request
    json_result = _check_result(method_name, result)
                  ^^^^^^^^^^^^^^^^^^^^^^^^^^^^^^^^^^
  File "/home/sobirjonovmuhammadazizbek/course-bot/venv/lib/python3.11/site-packages/telebot/apihelper.py", line 191, in _check_result
    raise ApiTelegramException(method_name, result, result_json)
telebot.apihelper.ApiTelegramException: A request to the Telegram API was unsuccessful. Error code: 409. Description: Conflict: terminated by other getUpdates request; make sure that only one bot instance is running
"
2024-04-02 07:49:19,139 (__init__.py:1147 MainThread) ERROR - TeleBot: "Threaded polling exception: A request to the Telegram API was unsuccessful. Error code: 409. Description: Conflict: terminated by other getUpdates request; make sure that only one bot instance is running"
2024-04-02 07:49:19,140 (__init__.py:1149 MainThread) ERROR - TeleBot: "Exception traceback:
Traceback (most recent call last):
  File "/home/sobirjonovmuhammadazizbek/course-bot/venv/lib/python3.11/site-packages/telebot/__init__.py", line 1140, in __threaded_polling
    polling_thread.raise_exceptions()
  File "/home/sobirjonovmuhammadazizbek/course-bot/venv/lib/python3.11/site-packages/telebot/util.py", line 110, in raise_exceptions
    raise self.exception_info
  File "/home/sobirjonovmuhammadazizbek/course-bot/venv/lib/python3.11/site-packages/telebot/util.py", line 92, in run
    task(*args, **kwargs)
  File "/home/sobirjonovmuhammadazizbek/course-bot/venv/lib/python3.11/site-packages/telebot/__init__.py", line 661, in __retrieve_updates
    updates = self.get_updates(offset=(self.last_update_id + 1),
             ^^^^^^^^^^^^^^^^^^^^^^^^^^^^^^^^^^^^^^^^^^^^^^^^^^^
  File "/home/sobirjonovmuhammadazizbek/course-bot/venv/lib/python3.11/site-packages/telebot/__init__.py", line 633, in get_updates
    json_updates = apihelper.get_updates(
                   ^^^^^^^^^^^^^^^^^^^^^^
  File "/home/sobirjonovmuhammadazizbek/course-bot/venv/lib/python3.11/site-packages/telebot/apihelper.py", line 321, in get_updates
    return _make_request(token, method_url, params=payload)
           ^^^^^^^^^^^^^^^^^^^^^^^^^^^^^^^^^^^^^^^^^^^^^^^^
  File "/home/sobirjonovmuhammadazizbek/course-bot/venv/lib/python3.11/site-packages/telebot/apihelper.py", line 164, in _make_request
    json_result = _check_result(method_name, result)
                  ^^^^^^^^^^^^^^^^^^^^^^^^^^^^^^^^^^
  File "/home/sobirjonovmuhammadazizbek/course-bot/venv/lib/python3.11/site-packages/telebot/apihelper.py", line 191, in _check_result
    raise ApiTelegramException(method_name, result, result_json)
telebot.apihelper.ApiTelegramException: A request to the Telegram API was unsuccessful. Error code: 409. Description: Conflict: terminated by other getUpdates request; make sure that only one bot instance is running
"
2024-04-02 07:49:23,288 (__init__.py:1147 MainThread) ERROR - TeleBot: "Threaded polling exception: A request to the Telegram API was unsuccessful. Error code: 409. Description: Conflict: terminated by other getUpdates request; make sure that only one bot instance is running"
2024-04-02 07:49:23,289 (__init__.py:1149 MainThread) ERROR - TeleBot: "Exception traceback:
Traceback (most recent call last):
  File "/home/sobirjonovmuhammadazizbek/course-bot/venv/lib/python3.11/site-packages/telebot/__init__.py", line 1140, in __threaded_polling
    polling_thread.raise_exceptions()
  File "/home/sobirjonovmuhammadazizbek/course-bot/venv/lib/python3.11/site-packages/telebot/util.py", line 110, in raise_exceptions
    raise self.exception_info
  File "/home/sobirjonovmuhammadazizbek/course-bot/venv/lib/python3.11/site-packages/telebot/util.py", line 92, in run
    task(*args, **kwargs)
  File "/home/sobirjonovmuhammadazizbek/course-bot/venv/lib/python3.11/site-packages/telebot/__init__.py", line 661, in __retrieve_updates
    updates = self.get_updates(offset=(self.last_update_id + 1),
             ^^^^^^^^^^^^^^^^^^^^^^^^^^^^^^^^^^^^^^^^^^^^^^^^^^^
  File "/home/sobirjonovmuhammadazizbek/course-bot/venv/lib/python3.11/site-packages/telebot/__init__.py", line 633, in get_updates
    json_updates = apihelper.get_updates(
                   ^^^^^^^^^^^^^^^^^^^^^^
  File "/home/sobirjonovmuhammadazizbek/course-bot/venv/lib/python3.11/site-packages/telebot/apihelper.py", line 321, in get_updates
    return _make_request(token, method_url, params=payload)
           ^^^^^^^^^^^^^^^^^^^^^^^^^^^^^^^^^^^^^^^^^^^^^^^^
  File "/home/sobirjonovmuhammadazizbek/course-bot/venv/lib/python3.11/site-packages/telebot/apihelper.py", line 164, in _make_request
    json_result = _check_result(method_name, result)
                  ^^^^^^^^^^^^^^^^^^^^^^^^^^^^^^^^^^
  File "/home/sobirjonovmuhammadazizbek/course-bot/venv/lib/python3.11/site-packages/telebot/apihelper.py", line 191, in _check_result
    raise ApiTelegramException(method_name, result, result_json)
telebot.apihelper.ApiTelegramException: A request to the Telegram API was unsuccessful. Error code: 409. Description: Conflict: terminated by other getUpdates request; make sure that only one bot instance is running
"
2024-04-02 07:49:26,685 (__init__.py:1147 MainThread) ERROR - TeleBot: "Threaded polling exception: A request to the Telegram API was unsuccessful. Error code: 409. Description: Conflict: terminated by other getUpdates request; make sure that only one bot instance is running"
2024-04-02 07:49:26,686 (__init__.py:1149 MainThread) ERROR - TeleBot: "Exception traceback:
Traceback (most recent call last):
  File "/home/sobirjonovmuhammadazizbek/course-bot/venv/lib/python3.11/site-packages/telebot/__init__.py", line 1140, in __threaded_polling
    polling_thread.raise_exceptions()
  File "/home/sobirjonovmuhammadazizbek/course-bot/venv/lib/python3.11/site-packages/telebot/util.py", line 110, in raise_exceptions
    raise self.exception_info
  File "/home/sobirjonovmuhammadazizbek/course-bot/venv/lib/python3.11/site-packages/telebot/util.py", line 92, in run
    task(*args, **kwargs)
  File "/home/sobirjonovmuhammadazizbek/course-bot/venv/lib/python3.11/site-packages/telebot/__init__.py", line 661, in __retrieve_updates
    updates = self.get_updates(offset=(self.last_update_id + 1),
             ^^^^^^^^^^^^^^^^^^^^^^^^^^^^^^^^^^^^^^^^^^^^^^^^^^^
  File "/home/sobirjonovmuhammadazizbek/course-bot/venv/lib/python3.11/site-packages/telebot/__init__.py", line 633, in get_updates
    json_updates = apihelper.get_updates(
                   ^^^^^^^^^^^^^^^^^^^^^^
  File "/home/sobirjonovmuhammadazizbek/course-bot/venv/lib/python3.11/site-packages/telebot/apihelper.py", line 321, in get_updates
    return _make_request(token, method_url, params=payload)
           ^^^^^^^^^^^^^^^^^^^^^^^^^^^^^^^^^^^^^^^^^^^^^^^^
  File "/home/sobirjonovmuhammadazizbek/course-bot/venv/lib/python3.11/site-packages/telebot/apihelper.py", line 164, in _make_request
    json_result = _check_result(method_name, result)
                  ^^^^^^^^^^^^^^^^^^^^^^^^^^^^^^^^^^
  File "/home/sobirjonovmuhammadazizbek/course-bot/venv/lib/python3.11/site-packages/telebot/apihelper.py", line 191, in _check_result
    raise ApiTelegramException(method_name, result, result_json)
telebot.apihelper.ApiTelegramException: A request to the Telegram API was unsuccessful. Error code: 409. Description: Conflict: terminated by other getUpdates request; make sure that only one bot instance is running
"
2024-04-02 07:49:34,832 (__init__.py:1147 MainThread) ERROR - TeleBot: "Threaded polling exception: A request to the Telegram API was unsuccessful. Error code: 409. Description: Conflict: terminated by other getUpdates request; make sure that only one bot instance is running"
2024-04-02 07:49:34,833 (__init__.py:1149 MainThread) ERROR - TeleBot: "Exception traceback:
Traceback (most recent call last):
  File "/home/sobirjonovmuhammadazizbek/course-bot/venv/lib/python3.11/site-packages/telebot/__init__.py", line 1140, in __threaded_polling
    polling_thread.raise_exceptions()
  File "/home/sobirjonovmuhammadazizbek/course-bot/venv/lib/python3.11/site-packages/telebot/util.py", line 110, in raise_exceptions
    raise self.exception_info
  File "/home/sobirjonovmuhammadazizbek/course-bot/venv/lib/python3.11/site-packages/telebot/util.py", line 92, in run
    task(*args, **kwargs)
  File "/home/sobirjonovmuhammadazizbek/course-bot/venv/lib/python3.11/site-packages/telebot/__init__.py", line 661, in __retrieve_updates
    updates = self.get_updates(offset=(self.last_update_id + 1),
             ^^^^^^^^^^^^^^^^^^^^^^^^^^^^^^^^^^^^^^^^^^^^^^^^^^^
  File "/home/sobirjonovmuhammadazizbek/course-bot/venv/lib/python3.11/site-packages/telebot/__init__.py", line 633, in get_updates
    json_updates = apihelper.get_updates(
                   ^^^^^^^^^^^^^^^^^^^^^^
  File "/home/sobirjonovmuhammadazizbek/course-bot/venv/lib/python3.11/site-packages/telebot/apihelper.py", line 321, in get_updates
    return _make_request(token, method_url, params=payload)
           ^^^^^^^^^^^^^^^^^^^^^^^^^^^^^^^^^^^^^^^^^^^^^^^^
  File "/home/sobirjonovmuhammadazizbek/course-bot/venv/lib/python3.11/site-packages/telebot/apihelper.py", line 164, in _make_request
    json_result = _check_result(method_name, result)
                  ^^^^^^^^^^^^^^^^^^^^^^^^^^^^^^^^^^
  File "/home/sobirjonovmuhammadazizbek/course-bot/venv/lib/python3.11/site-packages/telebot/apihelper.py", line 191, in _check_result
    raise ApiTelegramException(method_name, result, result_json)
telebot.apihelper.ApiTelegramException: A request to the Telegram API was unsuccessful. Error code: 409. Description: Conflict: terminated by other getUpdates request; make sure that only one bot instance is running
"
2024-04-02 07:49:38,231 (__init__.py:1147 MainThread) ERROR - TeleBot: "Threaded polling exception: A request to the Telegram API was unsuccessful. Error code: 409. Description: Conflict: terminated by other getUpdates request; make sure that only one bot instance is running"
2024-04-02 07:49:38,232 (__init__.py:1149 MainThread) ERROR - TeleBot: "Exception traceback:
Traceback (most recent call last):
  File "/home/sobirjonovmuhammadazizbek/course-bot/venv/lib/python3.11/site-packages/telebot/__init__.py", line 1140, in __threaded_polling
    polling_thread.raise_exceptions()
  File "/home/sobirjonovmuhammadazizbek/course-bot/venv/lib/python3.11/site-packages/telebot/util.py", line 110, in raise_exceptions
    raise self.exception_info
  File "/home/sobirjonovmuhammadazizbek/course-bot/venv/lib/python3.11/site-packages/telebot/util.py", line 92, in run
    task(*args, **kwargs)
  File "/home/sobirjonovmuhammadazizbek/course-bot/venv/lib/python3.11/site-packages/telebot/__init__.py", line 661, in __retrieve_updates
    updates = self.get_updates(offset=(self.last_update_id + 1),
             ^^^^^^^^^^^^^^^^^^^^^^^^^^^^^^^^^^^^^^^^^^^^^^^^^^^
  File "/home/sobirjonovmuhammadazizbek/course-bot/venv/lib/python3.11/site-packages/telebot/__init__.py", line 633, in get_updates
    json_updates = apihelper.get_updates(
                   ^^^^^^^^^^^^^^^^^^^^^^
  File "/home/sobirjonovmuhammadazizbek/course-bot/venv/lib/python3.11/site-packages/telebot/apihelper.py", line 321, in get_updates
    return _make_request(token, method_url, params=payload)
           ^^^^^^^^^^^^^^^^^^^^^^^^^^^^^^^^^^^^^^^^^^^^^^^^
  File "/home/sobirjonovmuhammadazizbek/course-bot/venv/lib/python3.11/site-packages/telebot/apihelper.py", line 164, in _make_request
    json_result = _check_result(method_name, result)
                  ^^^^^^^^^^^^^^^^^^^^^^^^^^^^^^^^^^
  File "/home/sobirjonovmuhammadazizbek/course-bot/venv/lib/python3.11/site-packages/telebot/apihelper.py", line 191, in _check_result
    raise ApiTelegramException(method_name, result, result_json)
telebot.apihelper.ApiTelegramException: A request to the Telegram API was unsuccessful. Error code: 409. Description: Conflict: terminated by other getUpdates request; make sure that only one bot instance is running
"
2024-04-02 07:49:54,379 (__init__.py:1147 MainThread) ERROR - TeleBot: "Threaded polling exception: A request to the Telegram API was unsuccessful. Error code: 409. Description: Conflict: terminated by other getUpdates request; make sure that only one bot instance is running"
2024-04-02 07:49:54,379 (__init__.py:1149 MainThread) ERROR - TeleBot: "Exception traceback:
Traceback (most recent call last):
  File "/home/sobirjonovmuhammadazizbek/course-bot/venv/lib/python3.11/site-packages/telebot/__init__.py", line 1140, in __threaded_polling
    polling_thread.raise_exceptions()
  File "/home/sobirjonovmuhammadazizbek/course-bot/venv/lib/python3.11/site-packages/telebot/util.py", line 110, in raise_exceptions
    raise self.exception_info
  File "/home/sobirjonovmuhammadazizbek/course-bot/venv/lib/python3.11/site-packages/telebot/util.py", line 92, in run
    task(*args, **kwargs)
  File "/home/sobirjonovmuhammadazizbek/course-bot/venv/lib/python3.11/site-packages/telebot/__init__.py", line 661, in __retrieve_updates
    updates = self.get_updates(offset=(self.last_update_id + 1),
             ^^^^^^^^^^^^^^^^^^^^^^^^^^^^^^^^^^^^^^^^^^^^^^^^^^^
  File "/home/sobirjonovmuhammadazizbek/course-bot/venv/lib/python3.11/site-packages/telebot/__init__.py", line 633, in get_updates
    json_updates = apihelper.get_updates(
                   ^^^^^^^^^^^^^^^^^^^^^^
  File "/home/sobirjonovmuhammadazizbek/course-bot/venv/lib/python3.11/site-packages/telebot/apihelper.py", line 321, in get_updates
    return _make_request(token, method_url, params=payload)
           ^^^^^^^^^^^^^^^^^^^^^^^^^^^^^^^^^^^^^^^^^^^^^^^^
  File "/home/sobirjonovmuhammadazizbek/course-bot/venv/lib/python3.11/site-packages/telebot/apihelper.py", line 164, in _make_request
    json_result = _check_result(method_name, result)
                  ^^^^^^^^^^^^^^^^^^^^^^^^^^^^^^^^^^
  File "/home/sobirjonovmuhammadazizbek/course-bot/venv/lib/python3.11/site-packages/telebot/apihelper.py", line 191, in _check_result
    raise ApiTelegramException(method_name, result, result_json)
telebot.apihelper.ApiTelegramException: A request to the Telegram API was unsuccessful. Error code: 409. Description: Conflict: terminated by other getUpdates request; make sure that only one bot instance is running
"
2024-04-02 07:49:57,779 (__init__.py:1147 MainThread) ERROR - TeleBot: "Threaded polling exception: A request to the Telegram API was unsuccessful. Error code: 409. Description: Conflict: terminated by other getUpdates request; make sure that only one bot instance is running"
2024-04-02 07:49:57,780 (__init__.py:1149 MainThread) ERROR - TeleBot: "Exception traceback:
Traceback (most recent call last):
  File "/home/sobirjonovmuhammadazizbek/course-bot/venv/lib/python3.11/site-packages/telebot/__init__.py", line 1140, in __threaded_polling
    polling_thread.raise_exceptions()
  File "/home/sobirjonovmuhammadazizbek/course-bot/venv/lib/python3.11/site-packages/telebot/util.py", line 110, in raise_exceptions
    raise self.exception_info
  File "/home/sobirjonovmuhammadazizbek/course-bot/venv/lib/python3.11/site-packages/telebot/util.py", line 92, in run
    task(*args, **kwargs)
  File "/home/sobirjonovmuhammadazizbek/course-bot/venv/lib/python3.11/site-packages/telebot/__init__.py", line 661, in __retrieve_updates
    updates = self.get_updates(offset=(self.last_update_id + 1),
             ^^^^^^^^^^^^^^^^^^^^^^^^^^^^^^^^^^^^^^^^^^^^^^^^^^^
  File "/home/sobirjonovmuhammadazizbek/course-bot/venv/lib/python3.11/site-packages/telebot/__init__.py", line 633, in get_updates
    json_updates = apihelper.get_updates(
                   ^^^^^^^^^^^^^^^^^^^^^^
  File "/home/sobirjonovmuhammadazizbek/course-bot/venv/lib/python3.11/site-packages/telebot/apihelper.py", line 321, in get_updates
    return _make_request(token, method_url, params=payload)
           ^^^^^^^^^^^^^^^^^^^^^^^^^^^^^^^^^^^^^^^^^^^^^^^^
  File "/home/sobirjonovmuhammadazizbek/course-bot/venv/lib/python3.11/site-packages/telebot/apihelper.py", line 164, in _make_request
    json_result = _check_result(method_name, result)
                  ^^^^^^^^^^^^^^^^^^^^^^^^^^^^^^^^^^
  File "/home/sobirjonovmuhammadazizbek/course-bot/venv/lib/python3.11/site-packages/telebot/apihelper.py", line 191, in _check_result
    raise ApiTelegramException(method_name, result, result_json)
telebot.apihelper.ApiTelegramException: A request to the Telegram API was unsuccessful. Error code: 409. Description: Conflict: terminated by other getUpdates request; make sure that only one bot instance is running
"
2024-04-02 07:50:29,926 (__init__.py:1147 MainThread) ERROR - TeleBot: "Threaded polling exception: A request to the Telegram API was unsuccessful. Error code: 409. Description: Conflict: terminated by other getUpdates request; make sure that only one bot instance is running"
2024-04-02 07:50:29,927 (__init__.py:1149 MainThread) ERROR - TeleBot: "Exception traceback:
Traceback (most recent call last):
  File "/home/sobirjonovmuhammadazizbek/course-bot/venv/lib/python3.11/site-packages/telebot/__init__.py", line 1140, in __threaded_polling
    polling_thread.raise_exceptions()
  File "/home/sobirjonovmuhammadazizbek/course-bot/venv/lib/python3.11/site-packages/telebot/util.py", line 110, in raise_exceptions
    raise self.exception_info
  File "/home/sobirjonovmuhammadazizbek/course-bot/venv/lib/python3.11/site-packages/telebot/util.py", line 92, in run
    task(*args, **kwargs)
  File "/home/sobirjonovmuhammadazizbek/course-bot/venv/lib/python3.11/site-packages/telebot/__init__.py", line 661, in __retrieve_updates
    updates = self.get_updates(offset=(self.last_update_id + 1),
             ^^^^^^^^^^^^^^^^^^^^^^^^^^^^^^^^^^^^^^^^^^^^^^^^^^^
  File "/home/sobirjonovmuhammadazizbek/course-bot/venv/lib/python3.11/site-packages/telebot/__init__.py", line 633, in get_updates
    json_updates = apihelper.get_updates(
                   ^^^^^^^^^^^^^^^^^^^^^^
  File "/home/sobirjonovmuhammadazizbek/course-bot/venv/lib/python3.11/site-packages/telebot/apihelper.py", line 321, in get_updates
    return _make_request(token, method_url, params=payload)
           ^^^^^^^^^^^^^^^^^^^^^^^^^^^^^^^^^^^^^^^^^^^^^^^^
  File "/home/sobirjonovmuhammadazizbek/course-bot/venv/lib/python3.11/site-packages/telebot/apihelper.py", line 164, in _make_request
    json_result = _check_result(method_name, result)
                  ^^^^^^^^^^^^^^^^^^^^^^^^^^^^^^^^^^
  File "/home/sobirjonovmuhammadazizbek/course-bot/venv/lib/python3.11/site-packages/telebot/apihelper.py", line 191, in _check_result
    raise ApiTelegramException(method_name, result, result_json)
telebot.apihelper.ApiTelegramException: A request to the Telegram API was unsuccessful. Error code: 409. Description: Conflict: terminated by other getUpdates request; make sure that only one bot instance is running
"
2024-04-02 07:50:33,323 (__init__.py:1147 MainThread) ERROR - TeleBot: "Threaded polling exception: A request to the Telegram API was unsuccessful. Error code: 409. Description: Conflict: terminated by other getUpdates request; make sure that only one bot instance is running"
2024-04-02 07:50:33,324 (__init__.py:1149 MainThread) ERROR - TeleBot: "Exception traceback:
Traceback (most recent call last):
  File "/home/sobirjonovmuhammadazizbek/course-bot/venv/lib/python3.11/site-packages/telebot/__init__.py", line 1140, in __threaded_polling
    polling_thread.raise_exceptions()
  File "/home/sobirjonovmuhammadazizbek/course-bot/venv/lib/python3.11/site-packages/telebot/util.py", line 110, in raise_exceptions
    raise self.exception_info
  File "/home/sobirjonovmuhammadazizbek/course-bot/venv/lib/python3.11/site-packages/telebot/util.py", line 92, in run
    task(*args, **kwargs)
  File "/home/sobirjonovmuhammadazizbek/course-bot/venv/lib/python3.11/site-packages/telebot/__init__.py", line 661, in __retrieve_updates
    updates = self.get_updates(offset=(self.last_update_id + 1),
             ^^^^^^^^^^^^^^^^^^^^^^^^^^^^^^^^^^^^^^^^^^^^^^^^^^^
  File "/home/sobirjonovmuhammadazizbek/course-bot/venv/lib/python3.11/site-packages/telebot/__init__.py", line 633, in get_updates
    json_updates = apihelper.get_updates(
                   ^^^^^^^^^^^^^^^^^^^^^^
  File "/home/sobirjonovmuhammadazizbek/course-bot/venv/lib/python3.11/site-packages/telebot/apihelper.py", line 321, in get_updates
    return _make_request(token, method_url, params=payload)
           ^^^^^^^^^^^^^^^^^^^^^^^^^^^^^^^^^^^^^^^^^^^^^^^^
  File "/home/sobirjonovmuhammadazizbek/course-bot/venv/lib/python3.11/site-packages/telebot/apihelper.py", line 164, in _make_request
    json_result = _check_result(method_name, result)
                  ^^^^^^^^^^^^^^^^^^^^^^^^^^^^^^^^^^
  File "/home/sobirjonovmuhammadazizbek/course-bot/venv/lib/python3.11/site-packages/telebot/apihelper.py", line 191, in _check_result
    raise ApiTelegramException(method_name, result, result_json)
telebot.apihelper.ApiTelegramException: A request to the Telegram API was unsuccessful. Error code: 409. Description: Conflict: terminated by other getUpdates request; make sure that only one bot instance is running
"
2024-04-02 07:51:22,099 (__init__.py:1147 MainThread) ERROR - TeleBot: "Threaded polling exception: A request to the Telegram API was unsuccessful. Error code: 409. Description: Conflict: terminated by other getUpdates request; make sure that only one bot instance is running"
2024-04-02 07:51:22,100 (__init__.py:1149 MainThread) ERROR - TeleBot: "Exception traceback:
Traceback (most recent call last):
  File "/home/sobirjonovmuhammadazizbek/course-bot/venv/lib/python3.11/site-packages/telebot/__init__.py", line 1140, in __threaded_polling
    polling_thread.raise_exceptions()
  File "/home/sobirjonovmuhammadazizbek/course-bot/venv/lib/python3.11/site-packages/telebot/util.py", line 110, in raise_exceptions
    raise self.exception_info
  File "/home/sobirjonovmuhammadazizbek/course-bot/venv/lib/python3.11/site-packages/telebot/util.py", line 92, in run
    task(*args, **kwargs)
  File "/home/sobirjonovmuhammadazizbek/course-bot/venv/lib/python3.11/site-packages/telebot/__init__.py", line 661, in __retrieve_updates
    updates = self.get_updates(offset=(self.last_update_id + 1),
             ^^^^^^^^^^^^^^^^^^^^^^^^^^^^^^^^^^^^^^^^^^^^^^^^^^^
  File "/home/sobirjonovmuhammadazizbek/course-bot/venv/lib/python3.11/site-packages/telebot/__init__.py", line 633, in get_updates
    json_updates = apihelper.get_updates(
                   ^^^^^^^^^^^^^^^^^^^^^^
  File "/home/sobirjonovmuhammadazizbek/course-bot/venv/lib/python3.11/site-packages/telebot/apihelper.py", line 321, in get_updates
    return _make_request(token, method_url, params=payload)
           ^^^^^^^^^^^^^^^^^^^^^^^^^^^^^^^^^^^^^^^^^^^^^^^^
  File "/home/sobirjonovmuhammadazizbek/course-bot/venv/lib/python3.11/site-packages/telebot/apihelper.py", line 164, in _make_request
    json_result = _check_result(method_name, result)
                  ^^^^^^^^^^^^^^^^^^^^^^^^^^^^^^^^^^
  File "/home/sobirjonovmuhammadazizbek/course-bot/venv/lib/python3.11/site-packages/telebot/apihelper.py", line 191, in _check_result
    raise ApiTelegramException(method_name, result, result_json)
telebot.apihelper.ApiTelegramException: A request to the Telegram API was unsuccessful. Error code: 409. Description: Conflict: terminated by other getUpdates request; make sure that only one bot instance is running
"
2024-04-02 07:51:25,916 (__init__.py:1147 MainThread) ERROR - TeleBot: "Threaded polling exception: A request to the Telegram API was unsuccessful. Error code: 409. Description: Conflict: terminated by other getUpdates request; make sure that only one bot instance is running"
2024-04-02 07:51:25,916 (__init__.py:1149 MainThread) ERROR - TeleBot: "Exception traceback:
Traceback (most recent call last):
  File "/home/sobirjonovmuhammadazizbek/course-bot/venv/lib/python3.11/site-packages/telebot/__init__.py", line 1140, in __threaded_polling
    polling_thread.raise_exceptions()
  File "/home/sobirjonovmuhammadazizbek/course-bot/venv/lib/python3.11/site-packages/telebot/util.py", line 110, in raise_exceptions
    raise self.exception_info
  File "/home/sobirjonovmuhammadazizbek/course-bot/venv/lib/python3.11/site-packages/telebot/util.py", line 92, in run
    task(*args, **kwargs)
  File "/home/sobirjonovmuhammadazizbek/course-bot/venv/lib/python3.11/site-packages/telebot/__init__.py", line 661, in __retrieve_updates
    updates = self.get_updates(offset=(self.last_update_id + 1),
             ^^^^^^^^^^^^^^^^^^^^^^^^^^^^^^^^^^^^^^^^^^^^^^^^^^^
  File "/home/sobirjonovmuhammadazizbek/course-bot/venv/lib/python3.11/site-packages/telebot/__init__.py", line 633, in get_updates
    json_updates = apihelper.get_updates(
                   ^^^^^^^^^^^^^^^^^^^^^^
  File "/home/sobirjonovmuhammadazizbek/course-bot/venv/lib/python3.11/site-packages/telebot/apihelper.py", line 321, in get_updates
    return _make_request(token, method_url, params=payload)
           ^^^^^^^^^^^^^^^^^^^^^^^^^^^^^^^^^^^^^^^^^^^^^^^^
  File "/home/sobirjonovmuhammadazizbek/course-bot/venv/lib/python3.11/site-packages/telebot/apihelper.py", line 164, in _make_request
    json_result = _check_result(method_name, result)
                  ^^^^^^^^^^^^^^^^^^^^^^^^^^^^^^^^^^
  File "/home/sobirjonovmuhammadazizbek/course-bot/venv/lib/python3.11/site-packages/telebot/apihelper.py", line 191, in _check_result
    raise ApiTelegramException(method_name, result, result_json)
telebot.apihelper.ApiTelegramException: A request to the Telegram API was unsuccessful. Error code: 409. Description: Conflict: terminated by other getUpdates request; make sure that only one bot instance is running
"
2024-04-02 07:51:30,223 (__init__.py:1147 MainThread) ERROR - TeleBot: "Threaded polling exception: A request to the Telegram API was unsuccessful. Error code: 409. Description: Conflict: terminated by other getUpdates request; make sure that only one bot instance is running"
2024-04-02 07:51:30,223 (__init__.py:1149 MainThread) ERROR - TeleBot: "Exception traceback:
Traceback (most recent call last):
  File "/home/sobirjonovmuhammadazizbek/course-bot/venv/lib/python3.11/site-packages/telebot/__init__.py", line 1140, in __threaded_polling
    polling_thread.raise_exceptions()
  File "/home/sobirjonovmuhammadazizbek/course-bot/venv/lib/python3.11/site-packages/telebot/util.py", line 110, in raise_exceptions
    raise self.exception_info
  File "/home/sobirjonovmuhammadazizbek/course-bot/venv/lib/python3.11/site-packages/telebot/util.py", line 92, in run
    task(*args, **kwargs)
  File "/home/sobirjonovmuhammadazizbek/course-bot/venv/lib/python3.11/site-packages/telebot/__init__.py", line 661, in __retrieve_updates
    updates = self.get_updates(offset=(self.last_update_id + 1),
             ^^^^^^^^^^^^^^^^^^^^^^^^^^^^^^^^^^^^^^^^^^^^^^^^^^^
  File "/home/sobirjonovmuhammadazizbek/course-bot/venv/lib/python3.11/site-packages/telebot/__init__.py", line 633, in get_updates
    json_updates = apihelper.get_updates(
                   ^^^^^^^^^^^^^^^^^^^^^^
  File "/home/sobirjonovmuhammadazizbek/course-bot/venv/lib/python3.11/site-packages/telebot/apihelper.py", line 321, in get_updates
    return _make_request(token, method_url, params=payload)
           ^^^^^^^^^^^^^^^^^^^^^^^^^^^^^^^^^^^^^^^^^^^^^^^^
  File "/home/sobirjonovmuhammadazizbek/course-bot/venv/lib/python3.11/site-packages/telebot/apihelper.py", line 164, in _make_request
    json_result = _check_result(method_name, result)
                  ^^^^^^^^^^^^^^^^^^^^^^^^^^^^^^^^^^
  File "/home/sobirjonovmuhammadazizbek/course-bot/venv/lib/python3.11/site-packages/telebot/apihelper.py", line 191, in _check_result
    raise ApiTelegramException(method_name, result, result_json)
telebot.apihelper.ApiTelegramException: A request to the Telegram API was unsuccessful. Error code: 409. Description: Conflict: terminated by other getUpdates request; make sure that only one bot instance is running
"
2024-04-02 07:51:33,475 (__init__.py:1147 MainThread) ERROR - TeleBot: "Threaded polling exception: A request to the Telegram API was unsuccessful. Error code: 409. Description: Conflict: terminated by other getUpdates request; make sure that only one bot instance is running"
2024-04-02 07:51:33,475 (__init__.py:1149 MainThread) ERROR - TeleBot: "Exception traceback:
Traceback (most recent call last):
  File "/home/sobirjonovmuhammadazizbek/course-bot/venv/lib/python3.11/site-packages/telebot/__init__.py", line 1140, in __threaded_polling
    polling_thread.raise_exceptions()
  File "/home/sobirjonovmuhammadazizbek/course-bot/venv/lib/python3.11/site-packages/telebot/util.py", line 110, in raise_exceptions
    raise self.exception_info
  File "/home/sobirjonovmuhammadazizbek/course-bot/venv/lib/python3.11/site-packages/telebot/util.py", line 92, in run
    task(*args, **kwargs)
  File "/home/sobirjonovmuhammadazizbek/course-bot/venv/lib/python3.11/site-packages/telebot/__init__.py", line 661, in __retrieve_updates
    updates = self.get_updates(offset=(self.last_update_id + 1),
             ^^^^^^^^^^^^^^^^^^^^^^^^^^^^^^^^^^^^^^^^^^^^^^^^^^^
  File "/home/sobirjonovmuhammadazizbek/course-bot/venv/lib/python3.11/site-packages/telebot/__init__.py", line 633, in get_updates
    json_updates = apihelper.get_updates(
                   ^^^^^^^^^^^^^^^^^^^^^^
  File "/home/sobirjonovmuhammadazizbek/course-bot/venv/lib/python3.11/site-packages/telebot/apihelper.py", line 321, in get_updates
    return _make_request(token, method_url, params=payload)
           ^^^^^^^^^^^^^^^^^^^^^^^^^^^^^^^^^^^^^^^^^^^^^^^^
  File "/home/sobirjonovmuhammadazizbek/course-bot/venv/lib/python3.11/site-packages/telebot/apihelper.py", line 164, in _make_request
    json_result = _check_result(method_name, result)
                  ^^^^^^^^^^^^^^^^^^^^^^^^^^^^^^^^^^
  File "/home/sobirjonovmuhammadazizbek/course-bot/venv/lib/python3.11/site-packages/telebot/apihelper.py", line 191, in _check_result
    raise ApiTelegramException(method_name, result, result_json)
telebot.apihelper.ApiTelegramException: A request to the Telegram API was unsuccessful. Error code: 409. Description: Conflict: terminated by other getUpdates request; make sure that only one bot instance is running
"
2024-04-02 07:51:38,623 (__init__.py:1147 MainThread) ERROR - TeleBot: "Threaded polling exception: A request to the Telegram API was unsuccessful. Error code: 409. Description: Conflict: terminated by other getUpdates request; make sure that only one bot instance is running"
2024-04-02 07:51:38,624 (__init__.py:1149 MainThread) ERROR - TeleBot: "Exception traceback:
Traceback (most recent call last):
  File "/home/sobirjonovmuhammadazizbek/course-bot/venv/lib/python3.11/site-packages/telebot/__init__.py", line 1140, in __threaded_polling
    polling_thread.raise_exceptions()
  File "/home/sobirjonovmuhammadazizbek/course-bot/venv/lib/python3.11/site-packages/telebot/util.py", line 110, in raise_exceptions
    raise self.exception_info
  File "/home/sobirjonovmuhammadazizbek/course-bot/venv/lib/python3.11/site-packages/telebot/util.py", line 92, in run
    task(*args, **kwargs)
  File "/home/sobirjonovmuhammadazizbek/course-bot/venv/lib/python3.11/site-packages/telebot/__init__.py", line 661, in __retrieve_updates
    updates = self.get_updates(offset=(self.last_update_id + 1),
             ^^^^^^^^^^^^^^^^^^^^^^^^^^^^^^^^^^^^^^^^^^^^^^^^^^^
  File "/home/sobirjonovmuhammadazizbek/course-bot/venv/lib/python3.11/site-packages/telebot/__init__.py", line 633, in get_updates
    json_updates = apihelper.get_updates(
                   ^^^^^^^^^^^^^^^^^^^^^^
  File "/home/sobirjonovmuhammadazizbek/course-bot/venv/lib/python3.11/site-packages/telebot/apihelper.py", line 321, in get_updates
    return _make_request(token, method_url, params=payload)
           ^^^^^^^^^^^^^^^^^^^^^^^^^^^^^^^^^^^^^^^^^^^^^^^^
  File "/home/sobirjonovmuhammadazizbek/course-bot/venv/lib/python3.11/site-packages/telebot/apihelper.py", line 164, in _make_request
    json_result = _check_result(method_name, result)
                  ^^^^^^^^^^^^^^^^^^^^^^^^^^^^^^^^^^
  File "/home/sobirjonovmuhammadazizbek/course-bot/venv/lib/python3.11/site-packages/telebot/apihelper.py", line 191, in _check_result
    raise ApiTelegramException(method_name, result, result_json)
telebot.apihelper.ApiTelegramException: A request to the Telegram API was unsuccessful. Error code: 409. Description: Conflict: terminated by other getUpdates request; make sure that only one bot instance is running
"
Traceback (most recent call last):
  File "/home/sobirjonovmuhammadazizbek/course-bot/bot.py", line 1, in <module>
    from telebot import TeleBot
ModuleNotFoundError: No module named 'telebot'
2024-04-02 08:14:52,404 (__init__.py:1147 MainThread) ERROR - TeleBot: "Threaded polling exception: A request to the Telegram API was unsuccessful. Error code: 409. Description: Conflict: terminated by other getUpdates request; make sure that only one bot instance is running"
2024-04-02 08:14:52,405 (__init__.py:1149 MainThread) ERROR - TeleBot: "Exception traceback:
Traceback (most recent call last):
  File "/home/sobirjonovmuhammadazizbek/course-bot/venv/lib/python3.11/site-packages/telebot/__init__.py", line 1140, in __threaded_polling
    polling_thread.raise_exceptions()
  File "/home/sobirjonovmuhammadazizbek/course-bot/venv/lib/python3.11/site-packages/telebot/util.py", line 110, in raise_exceptions
    raise self.exception_info
  File "/home/sobirjonovmuhammadazizbek/course-bot/venv/lib/python3.11/site-packages/telebot/util.py", line 92, in run
    task(*args, **kwargs)
  File "/home/sobirjonovmuhammadazizbek/course-bot/venv/lib/python3.11/site-packages/telebot/__init__.py", line 661, in __retrieve_updates
    updates = self.get_updates(offset=(self.last_update_id + 1),
             ^^^^^^^^^^^^^^^^^^^^^^^^^^^^^^^^^^^^^^^^^^^^^^^^^^^
  File "/home/sobirjonovmuhammadazizbek/course-bot/venv/lib/python3.11/site-packages/telebot/__init__.py", line 633, in get_updates
    json_updates = apihelper.get_updates(
                   ^^^^^^^^^^^^^^^^^^^^^^
  File "/home/sobirjonovmuhammadazizbek/course-bot/venv/lib/python3.11/site-packages/telebot/apihelper.py", line 321, in get_updates
    return _make_request(token, method_url, params=payload)
           ^^^^^^^^^^^^^^^^^^^^^^^^^^^^^^^^^^^^^^^^^^^^^^^^
  File "/home/sobirjonovmuhammadazizbek/course-bot/venv/lib/python3.11/site-packages/telebot/apihelper.py", line 164, in _make_request
    json_result = _check_result(method_name, result)
                  ^^^^^^^^^^^^^^^^^^^^^^^^^^^^^^^^^^
  File "/home/sobirjonovmuhammadazizbek/course-bot/venv/lib/python3.11/site-packages/telebot/apihelper.py", line 191, in _check_result
    raise ApiTelegramException(method_name, result, result_json)
telebot.apihelper.ApiTelegramException: A request to the Telegram API was unsuccessful. Error code: 409. Description: Conflict: terminated by other getUpdates request; make sure that only one bot instance is running
"
2024-04-02 08:14:59,761 (__init__.py:1147 MainThread) ERROR - TeleBot: "Threaded polling exception: A request to the Telegram API was unsuccessful. Error code: 409. Description: Conflict: terminated by other getUpdates request; make sure that only one bot instance is running"
2024-04-02 08:14:59,762 (__init__.py:1149 MainThread) ERROR - TeleBot: "Exception traceback:
Traceback (most recent call last):
  File "/home/sobirjonovmuhammadazizbek/course-bot/venv/lib/python3.11/site-packages/telebot/__init__.py", line 1140, in __threaded_polling
    polling_thread.raise_exceptions()
  File "/home/sobirjonovmuhammadazizbek/course-bot/venv/lib/python3.11/site-packages/telebot/util.py", line 110, in raise_exceptions
    raise self.exception_info
  File "/home/sobirjonovmuhammadazizbek/course-bot/venv/lib/python3.11/site-packages/telebot/util.py", line 92, in run
    task(*args, **kwargs)
  File "/home/sobirjonovmuhammadazizbek/course-bot/venv/lib/python3.11/site-packages/telebot/__init__.py", line 661, in __retrieve_updates
    updates = self.get_updates(offset=(self.last_update_id + 1),
             ^^^^^^^^^^^^^^^^^^^^^^^^^^^^^^^^^^^^^^^^^^^^^^^^^^^
  File "/home/sobirjonovmuhammadazizbek/course-bot/venv/lib/python3.11/site-packages/telebot/__init__.py", line 633, in get_updates
    json_updates = apihelper.get_updates(
                   ^^^^^^^^^^^^^^^^^^^^^^
  File "/home/sobirjonovmuhammadazizbek/course-bot/venv/lib/python3.11/site-packages/telebot/apihelper.py", line 321, in get_updates
    return _make_request(token, method_url, params=payload)
           ^^^^^^^^^^^^^^^^^^^^^^^^^^^^^^^^^^^^^^^^^^^^^^^^
  File "/home/sobirjonovmuhammadazizbek/course-bot/venv/lib/python3.11/site-packages/telebot/apihelper.py", line 164, in _make_request
    json_result = _check_result(method_name, result)
                  ^^^^^^^^^^^^^^^^^^^^^^^^^^^^^^^^^^
  File "/home/sobirjonovmuhammadazizbek/course-bot/venv/lib/python3.11/site-packages/telebot/apihelper.py", line 191, in _check_result
    raise ApiTelegramException(method_name, result, result_json)
telebot.apihelper.ApiTelegramException: A request to the Telegram API was unsuccessful. Error code: 409. Description: Conflict: terminated by other getUpdates request; make sure that only one bot instance is running
"
2024-04-02 08:15:04,192 (__init__.py:1147 MainThread) ERROR - TeleBot: "Threaded polling exception: A request to the Telegram API was unsuccessful. Error code: 409. Description: Conflict: terminated by other getUpdates request; make sure that only one bot instance is running"
2024-04-02 08:15:04,193 (__init__.py:1149 MainThread) ERROR - TeleBot: "Exception traceback:
Traceback (most recent call last):
  File "/home/sobirjonovmuhammadazizbek/course-bot/venv/lib/python3.11/site-packages/telebot/__init__.py", line 1140, in __threaded_polling
    polling_thread.raise_exceptions()
  File "/home/sobirjonovmuhammadazizbek/course-bot/venv/lib/python3.11/site-packages/telebot/util.py", line 110, in raise_exceptions
    raise self.exception_info
  File "/home/sobirjonovmuhammadazizbek/course-bot/venv/lib/python3.11/site-packages/telebot/util.py", line 92, in run
    task(*args, **kwargs)
  File "/home/sobirjonovmuhammadazizbek/course-bot/venv/lib/python3.11/site-packages/telebot/__init__.py", line 661, in __retrieve_updates
    updates = self.get_updates(offset=(self.last_update_id + 1),
             ^^^^^^^^^^^^^^^^^^^^^^^^^^^^^^^^^^^^^^^^^^^^^^^^^^^
  File "/home/sobirjonovmuhammadazizbek/course-bot/venv/lib/python3.11/site-packages/telebot/__init__.py", line 633, in get_updates
    json_updates = apihelper.get_updates(
                   ^^^^^^^^^^^^^^^^^^^^^^
  File "/home/sobirjonovmuhammadazizbek/course-bot/venv/lib/python3.11/site-packages/telebot/apihelper.py", line 321, in get_updates
    return _make_request(token, method_url, params=payload)
           ^^^^^^^^^^^^^^^^^^^^^^^^^^^^^^^^^^^^^^^^^^^^^^^^
  File "/home/sobirjonovmuhammadazizbek/course-bot/venv/lib/python3.11/site-packages/telebot/apihelper.py", line 164, in _make_request
    json_result = _check_result(method_name, result)
                  ^^^^^^^^^^^^^^^^^^^^^^^^^^^^^^^^^^
  File "/home/sobirjonovmuhammadazizbek/course-bot/venv/lib/python3.11/site-packages/telebot/apihelper.py", line 191, in _check_result
    raise ApiTelegramException(method_name, result, result_json)
telebot.apihelper.ApiTelegramException: A request to the Telegram API was unsuccessful. Error code: 409. Description: Conflict: terminated by other getUpdates request; make sure that only one bot instance is running
"
2024-04-02 08:15:08,983 (__init__.py:1147 MainThread) ERROR - TeleBot: "Threaded polling exception: A request to the Telegram API was unsuccessful. Error code: 409. Description: Conflict: terminated by other getUpdates request; make sure that only one bot instance is running"
2024-04-02 08:15:08,984 (__init__.py:1149 MainThread) ERROR - TeleBot: "Exception traceback:
Traceback (most recent call last):
  File "/home/sobirjonovmuhammadazizbek/course-bot/venv/lib/python3.11/site-packages/telebot/__init__.py", line 1140, in __threaded_polling
    polling_thread.raise_exceptions()
  File "/home/sobirjonovmuhammadazizbek/course-bot/venv/lib/python3.11/site-packages/telebot/util.py", line 110, in raise_exceptions
    raise self.exception_info
  File "/home/sobirjonovmuhammadazizbek/course-bot/venv/lib/python3.11/site-packages/telebot/util.py", line 92, in run
    task(*args, **kwargs)
  File "/home/sobirjonovmuhammadazizbek/course-bot/venv/lib/python3.11/site-packages/telebot/__init__.py", line 661, in __retrieve_updates
    updates = self.get_updates(offset=(self.last_update_id + 1),
             ^^^^^^^^^^^^^^^^^^^^^^^^^^^^^^^^^^^^^^^^^^^^^^^^^^^
  File "/home/sobirjonovmuhammadazizbek/course-bot/venv/lib/python3.11/site-packages/telebot/__init__.py", line 633, in get_updates
    json_updates = apihelper.get_updates(
                   ^^^^^^^^^^^^^^^^^^^^^^
  File "/home/sobirjonovmuhammadazizbek/course-bot/venv/lib/python3.11/site-packages/telebot/apihelper.py", line 321, in get_updates
    return _make_request(token, method_url, params=payload)
           ^^^^^^^^^^^^^^^^^^^^^^^^^^^^^^^^^^^^^^^^^^^^^^^^
  File "/home/sobirjonovmuhammadazizbek/course-bot/venv/lib/python3.11/site-packages/telebot/apihelper.py", line 164, in _make_request
    json_result = _check_result(method_name, result)
                  ^^^^^^^^^^^^^^^^^^^^^^^^^^^^^^^^^^
  File "/home/sobirjonovmuhammadazizbek/course-bot/venv/lib/python3.11/site-packages/telebot/apihelper.py", line 191, in _check_result
    raise ApiTelegramException(method_name, result, result_json)
telebot.apihelper.ApiTelegramException: A request to the Telegram API was unsuccessful. Error code: 409. Description: Conflict: terminated by other getUpdates request; make sure that only one bot instance is running
"
2024-04-02 08:15:15,467 (__init__.py:1147 MainThread) ERROR - TeleBot: "Threaded polling exception: A request to the Telegram API was unsuccessful. Error code: 409. Description: Conflict: terminated by other getUpdates request; make sure that only one bot instance is running"
2024-04-02 08:15:15,469 (__init__.py:1149 MainThread) ERROR - TeleBot: "Exception traceback:
Traceback (most recent call last):
  File "/home/sobirjonovmuhammadazizbek/course-bot/venv/lib/python3.11/site-packages/telebot/__init__.py", line 1140, in __threaded_polling
    polling_thread.raise_exceptions()
  File "/home/sobirjonovmuhammadazizbek/course-bot/venv/lib/python3.11/site-packages/telebot/util.py", line 110, in raise_exceptions
    raise self.exception_info
  File "/home/sobirjonovmuhammadazizbek/course-bot/venv/lib/python3.11/site-packages/telebot/util.py", line 92, in run
    task(*args, **kwargs)
  File "/home/sobirjonovmuhammadazizbek/course-bot/venv/lib/python3.11/site-packages/telebot/__init__.py", line 661, in __retrieve_updates
    updates = self.get_updates(offset=(self.last_update_id + 1),
             ^^^^^^^^^^^^^^^^^^^^^^^^^^^^^^^^^^^^^^^^^^^^^^^^^^^
  File "/home/sobirjonovmuhammadazizbek/course-bot/venv/lib/python3.11/site-packages/telebot/__init__.py", line 633, in get_updates
    json_updates = apihelper.get_updates(
                   ^^^^^^^^^^^^^^^^^^^^^^
  File "/home/sobirjonovmuhammadazizbek/course-bot/venv/lib/python3.11/site-packages/telebot/apihelper.py", line 321, in get_updates
    return _make_request(token, method_url, params=payload)
           ^^^^^^^^^^^^^^^^^^^^^^^^^^^^^^^^^^^^^^^^^^^^^^^^
  File "/home/sobirjonovmuhammadazizbek/course-bot/venv/lib/python3.11/site-packages/telebot/apihelper.py", line 164, in _make_request
    json_result = _check_result(method_name, result)
                  ^^^^^^^^^^^^^^^^^^^^^^^^^^^^^^^^^^
  File "/home/sobirjonovmuhammadazizbek/course-bot/venv/lib/python3.11/site-packages/telebot/apihelper.py", line 191, in _check_result
    raise ApiTelegramException(method_name, result, result_json)
telebot.apihelper.ApiTelegramException: A request to the Telegram API was unsuccessful. Error code: 409. Description: Conflict: terminated by other getUpdates request; make sure that only one bot instance is running
"
2024-04-02 08:15:21,748 (__init__.py:1147 MainThread) ERROR - TeleBot: "Threaded polling exception: A request to the Telegram API was unsuccessful. Error code: 409. Description: Conflict: terminated by other getUpdates request; make sure that only one bot instance is running"
2024-04-02 08:15:21,748 (__init__.py:1149 MainThread) ERROR - TeleBot: "Exception traceback:
Traceback (most recent call last):
  File "/home/sobirjonovmuhammadazizbek/course-bot/venv/lib/python3.11/site-packages/telebot/__init__.py", line 1140, in __threaded_polling
    polling_thread.raise_exceptions()
  File "/home/sobirjonovmuhammadazizbek/course-bot/venv/lib/python3.11/site-packages/telebot/util.py", line 110, in raise_exceptions
    raise self.exception_info
  File "/home/sobirjonovmuhammadazizbek/course-bot/venv/lib/python3.11/site-packages/telebot/util.py", line 92, in run
    task(*args, **kwargs)
  File "/home/sobirjonovmuhammadazizbek/course-bot/venv/lib/python3.11/site-packages/telebot/__init__.py", line 661, in __retrieve_updates
    updates = self.get_updates(offset=(self.last_update_id + 1),
             ^^^^^^^^^^^^^^^^^^^^^^^^^^^^^^^^^^^^^^^^^^^^^^^^^^^
  File "/home/sobirjonovmuhammadazizbek/course-bot/venv/lib/python3.11/site-packages/telebot/__init__.py", line 633, in get_updates
    json_updates = apihelper.get_updates(
                   ^^^^^^^^^^^^^^^^^^^^^^
  File "/home/sobirjonovmuhammadazizbek/course-bot/venv/lib/python3.11/site-packages/telebot/apihelper.py", line 321, in get_updates
    return _make_request(token, method_url, params=payload)
           ^^^^^^^^^^^^^^^^^^^^^^^^^^^^^^^^^^^^^^^^^^^^^^^^
  File "/home/sobirjonovmuhammadazizbek/course-bot/venv/lib/python3.11/site-packages/telebot/apihelper.py", line 164, in _make_request
    json_result = _check_result(method_name, result)
                  ^^^^^^^^^^^^^^^^^^^^^^^^^^^^^^^^^^
  File "/home/sobirjonovmuhammadazizbek/course-bot/venv/lib/python3.11/site-packages/telebot/apihelper.py", line 191, in _check_result
    raise ApiTelegramException(method_name, result, result_json)
telebot.apihelper.ApiTelegramException: A request to the Telegram API was unsuccessful. Error code: 409. Description: Conflict: terminated by other getUpdates request; make sure that only one bot instance is running
"
2024-04-02 08:15:34,321 (__init__.py:1147 MainThread) ERROR - TeleBot: "Threaded polling exception: A request to the Telegram API was unsuccessful. Error code: 409. Description: Conflict: terminated by other getUpdates request; make sure that only one bot instance is running"
2024-04-02 08:15:34,322 (__init__.py:1149 MainThread) ERROR - TeleBot: "Exception traceback:
Traceback (most recent call last):
  File "/home/sobirjonovmuhammadazizbek/course-bot/venv/lib/python3.11/site-packages/telebot/__init__.py", line 1140, in __threaded_polling
    polling_thread.raise_exceptions()
  File "/home/sobirjonovmuhammadazizbek/course-bot/venv/lib/python3.11/site-packages/telebot/util.py", line 110, in raise_exceptions
    raise self.exception_info
  File "/home/sobirjonovmuhammadazizbek/course-bot/venv/lib/python3.11/site-packages/telebot/util.py", line 92, in run
    task(*args, **kwargs)
  File "/home/sobirjonovmuhammadazizbek/course-bot/venv/lib/python3.11/site-packages/telebot/__init__.py", line 661, in __retrieve_updates
    updates = self.get_updates(offset=(self.last_update_id + 1),
             ^^^^^^^^^^^^^^^^^^^^^^^^^^^^^^^^^^^^^^^^^^^^^^^^^^^
  File "/home/sobirjonovmuhammadazizbek/course-bot/venv/lib/python3.11/site-packages/telebot/__init__.py", line 633, in get_updates
    json_updates = apihelper.get_updates(
                   ^^^^^^^^^^^^^^^^^^^^^^
  File "/home/sobirjonovmuhammadazizbek/course-bot/venv/lib/python3.11/site-packages/telebot/apihelper.py", line 321, in get_updates
    return _make_request(token, method_url, params=payload)
           ^^^^^^^^^^^^^^^^^^^^^^^^^^^^^^^^^^^^^^^^^^^^^^^^
  File "/home/sobirjonovmuhammadazizbek/course-bot/venv/lib/python3.11/site-packages/telebot/apihelper.py", line 164, in _make_request
    json_result = _check_result(method_name, result)
                  ^^^^^^^^^^^^^^^^^^^^^^^^^^^^^^^^^^
  File "/home/sobirjonovmuhammadazizbek/course-bot/venv/lib/python3.11/site-packages/telebot/apihelper.py", line 191, in _check_result
    raise ApiTelegramException(method_name, result, result_json)
telebot.apihelper.ApiTelegramException: A request to the Telegram API was unsuccessful. Error code: 409. Description: Conflict: terminated by other getUpdates request; make sure that only one bot instance is running
"
Error checking if user is logged: no such table: referrals
An error occurred in run: ('Connection aborted.', RemoteDisconnected('Remote end closed connection without response'))
2024-04-04 08:53:12,461 (__init__.py:1147 MainThread) ERROR - TeleBot: "Threaded polling exception: A request to the Telegram API was unsuccessful. Error code: 409. Description: Conflict: terminated by other getUpdates request; make sure that only one bot instance is running"
2024-04-04 08:53:12,462 (__init__.py:1149 MainThread) ERROR - TeleBot: "Exception traceback:
Traceback (most recent call last):
  File "/home/sobirjonovmuhammadazizbek/course-bot/venv/lib/python3.11/site-packages/telebot/__init__.py", line 1140, in __threaded_polling
    polling_thread.raise_exceptions()
  File "/home/sobirjonovmuhammadazizbek/course-bot/venv/lib/python3.11/site-packages/telebot/util.py", line 110, in raise_exceptions
    raise self.exception_info
  File "/home/sobirjonovmuhammadazizbek/course-bot/venv/lib/python3.11/site-packages/telebot/util.py", line 92, in run
    task(*args, **kwargs)
  File "/home/sobirjonovmuhammadazizbek/course-bot/venv/lib/python3.11/site-packages/telebot/__init__.py", line 661, in __retrieve_updates
    updates = self.get_updates(offset=(self.last_update_id + 1),
             ^^^^^^^^^^^^^^^^^^^^^^^^^^^^^^^^^^^^^^^^^^^^^^^^^^^
  File "/home/sobirjonovmuhammadazizbek/course-bot/venv/lib/python3.11/site-packages/telebot/__init__.py", line 633, in get_updates
    json_updates = apihelper.get_updates(
                   ^^^^^^^^^^^^^^^^^^^^^^
  File "/home/sobirjonovmuhammadazizbek/course-bot/venv/lib/python3.11/site-packages/telebot/apihelper.py", line 321, in get_updates
    return _make_request(token, method_url, params=payload)
           ^^^^^^^^^^^^^^^^^^^^^^^^^^^^^^^^^^^^^^^^^^^^^^^^
  File "/home/sobirjonovmuhammadazizbek/course-bot/venv/lib/python3.11/site-packages/telebot/apihelper.py", line 164, in _make_request
    json_result = _check_result(method_name, result)
                  ^^^^^^^^^^^^^^^^^^^^^^^^^^^^^^^^^^
  File "/home/sobirjonovmuhammadazizbek/course-bot/venv/lib/python3.11/site-packages/telebot/apihelper.py", line 191, in _check_result
    raise ApiTelegramException(method_name, result, result_json)
telebot.apihelper.ApiTelegramException: A request to the Telegram API was unsuccessful. Error code: 409. Description: Conflict: terminated by other getUpdates request; make sure that only one bot instance is running
"
2024-04-04 08:53:15,868 (__init__.py:1147 MainThread) ERROR - TeleBot: "Threaded polling exception: A request to the Telegram API was unsuccessful. Error code: 409. Description: Conflict: terminated by other getUpdates request; make sure that only one bot instance is running"
2024-04-04 08:53:15,869 (__init__.py:1149 MainThread) ERROR - TeleBot: "Exception traceback:
Traceback (most recent call last):
  File "/home/sobirjonovmuhammadazizbek/course-bot/venv/lib/python3.11/site-packages/telebot/__init__.py", line 1140, in __threaded_polling
    polling_thread.raise_exceptions()
  File "/home/sobirjonovmuhammadazizbek/course-bot/venv/lib/python3.11/site-packages/telebot/util.py", line 110, in raise_exceptions
    raise self.exception_info
  File "/home/sobirjonovmuhammadazizbek/course-bot/venv/lib/python3.11/site-packages/telebot/util.py", line 92, in run
    task(*args, **kwargs)
  File "/home/sobirjonovmuhammadazizbek/course-bot/venv/lib/python3.11/site-packages/telebot/__init__.py", line 661, in __retrieve_updates
    updates = self.get_updates(offset=(self.last_update_id + 1),
             ^^^^^^^^^^^^^^^^^^^^^^^^^^^^^^^^^^^^^^^^^^^^^^^^^^^
  File "/home/sobirjonovmuhammadazizbek/course-bot/venv/lib/python3.11/site-packages/telebot/__init__.py", line 633, in get_updates
    json_updates = apihelper.get_updates(
                   ^^^^^^^^^^^^^^^^^^^^^^
  File "/home/sobirjonovmuhammadazizbek/course-bot/venv/lib/python3.11/site-packages/telebot/apihelper.py", line 321, in get_updates
    return _make_request(token, method_url, params=payload)
           ^^^^^^^^^^^^^^^^^^^^^^^^^^^^^^^^^^^^^^^^^^^^^^^^
  File "/home/sobirjonovmuhammadazizbek/course-bot/venv/lib/python3.11/site-packages/telebot/apihelper.py", line 164, in _make_request
    json_result = _check_result(method_name, result)
                  ^^^^^^^^^^^^^^^^^^^^^^^^^^^^^^^^^^
  File "/home/sobirjonovmuhammadazizbek/course-bot/venv/lib/python3.11/site-packages/telebot/apihelper.py", line 191, in _check_result
    raise ApiTelegramException(method_name, result, result_json)
telebot.apihelper.ApiTelegramException: A request to the Telegram API was unsuccessful. Error code: 409. Description: Conflict: terminated by other getUpdates request; make sure that only one bot instance is running
"
2024-04-04 08:53:16,264 (__init__.py:1147 MainThread) ERROR - TeleBot: "Threaded polling exception: A request to the Telegram API was unsuccessful. Error code: 409. Description: Conflict: terminated by other getUpdates request; make sure that only one bot instance is running"
2024-04-04 08:53:16,265 (__init__.py:1149 MainThread) ERROR - TeleBot: "Exception traceback:
Traceback (most recent call last):
  File "/home/sobirjonovmuhammadazizbek/course-bot/venv/lib/python3.11/site-packages/telebot/__init__.py", line 1140, in __threaded_polling
    polling_thread.raise_exceptions()
  File "/home/sobirjonovmuhammadazizbek/course-bot/venv/lib/python3.11/site-packages/telebot/util.py", line 110, in raise_exceptions
    raise self.exception_info
  File "/home/sobirjonovmuhammadazizbek/course-bot/venv/lib/python3.11/site-packages/telebot/util.py", line 92, in run
    task(*args, **kwargs)
  File "/home/sobirjonovmuhammadazizbek/course-bot/venv/lib/python3.11/site-packages/telebot/__init__.py", line 661, in __retrieve_updates
    updates = self.get_updates(offset=(self.last_update_id + 1),
             ^^^^^^^^^^^^^^^^^^^^^^^^^^^^^^^^^^^^^^^^^^^^^^^^^^^
  File "/home/sobirjonovmuhammadazizbek/course-bot/venv/lib/python3.11/site-packages/telebot/__init__.py", line 633, in get_updates
    json_updates = apihelper.get_updates(
                   ^^^^^^^^^^^^^^^^^^^^^^
  File "/home/sobirjonovmuhammadazizbek/course-bot/venv/lib/python3.11/site-packages/telebot/apihelper.py", line 321, in get_updates
    return _make_request(token, method_url, params=payload)
           ^^^^^^^^^^^^^^^^^^^^^^^^^^^^^^^^^^^^^^^^^^^^^^^^
  File "/home/sobirjonovmuhammadazizbek/course-bot/venv/lib/python3.11/site-packages/telebot/apihelper.py", line 164, in _make_request
    json_result = _check_result(method_name, result)
                  ^^^^^^^^^^^^^^^^^^^^^^^^^^^^^^^^^^
  File "/home/sobirjonovmuhammadazizbek/course-bot/venv/lib/python3.11/site-packages/telebot/apihelper.py", line 191, in _check_result
    raise ApiTelegramException(method_name, result, result_json)
telebot.apihelper.ApiTelegramException: A request to the Telegram API was unsuccessful. Error code: 409. Description: Conflict: terminated by other getUpdates request; make sure that only one bot instance is running
"
2024-04-04 08:53:19,916 (__init__.py:1147 MainThread) ERROR - TeleBot: "Threaded polling exception: A request to the Telegram API was unsuccessful. Error code: 409. Description: Conflict: terminated by other getUpdates request; make sure that only one bot instance is running"
2024-04-04 08:53:19,917 (__init__.py:1149 MainThread) ERROR - TeleBot: "Exception traceback:
Traceback (most recent call last):
  File "/home/sobirjonovmuhammadazizbek/course-bot/venv/lib/python3.11/site-packages/telebot/__init__.py", line 1140, in __threaded_polling
    polling_thread.raise_exceptions()
  File "/home/sobirjonovmuhammadazizbek/course-bot/venv/lib/python3.11/site-packages/telebot/util.py", line 110, in raise_exceptions
    raise self.exception_info
  File "/home/sobirjonovmuhammadazizbek/course-bot/venv/lib/python3.11/site-packages/telebot/util.py", line 92, in run
    task(*args, **kwargs)
  File "/home/sobirjonovmuhammadazizbek/course-bot/venv/lib/python3.11/site-packages/telebot/__init__.py", line 661, in __retrieve_updates
    updates = self.get_updates(offset=(self.last_update_id + 1),
             ^^^^^^^^^^^^^^^^^^^^^^^^^^^^^^^^^^^^^^^^^^^^^^^^^^^
  File "/home/sobirjonovmuhammadazizbek/course-bot/venv/lib/python3.11/site-packages/telebot/__init__.py", line 633, in get_updates
    json_updates = apihelper.get_updates(
                   ^^^^^^^^^^^^^^^^^^^^^^
  File "/home/sobirjonovmuhammadazizbek/course-bot/venv/lib/python3.11/site-packages/telebot/apihelper.py", line 321, in get_updates
    return _make_request(token, method_url, params=payload)
           ^^^^^^^^^^^^^^^^^^^^^^^^^^^^^^^^^^^^^^^^^^^^^^^^
  File "/home/sobirjonovmuhammadazizbek/course-bot/venv/lib/python3.11/site-packages/telebot/apihelper.py", line 164, in _make_request
    json_result = _check_result(method_name, result)
                  ^^^^^^^^^^^^^^^^^^^^^^^^^^^^^^^^^^
  File "/home/sobirjonovmuhammadazizbek/course-bot/venv/lib/python3.11/site-packages/telebot/apihelper.py", line 191, in _check_result
    raise ApiTelegramException(method_name, result, result_json)
telebot.apihelper.ApiTelegramException: A request to the Telegram API was unsuccessful. Error code: 409. Description: Conflict: terminated by other getUpdates request; make sure that only one bot instance is running
"
2024-04-04 08:53:20,565 (__init__.py:1147 MainThread) ERROR - TeleBot: "Threaded polling exception: A request to the Telegram API was unsuccessful. Error code: 409. Description: Conflict: terminated by other getUpdates request; make sure that only one bot instance is running"
2024-04-04 08:53:20,565 (__init__.py:1149 MainThread) ERROR - TeleBot: "Exception traceback:
Traceback (most recent call last):
  File "/home/sobirjonovmuhammadazizbek/course-bot/venv/lib/python3.11/site-packages/telebot/__init__.py", line 1140, in __threaded_polling
    polling_thread.raise_exceptions()
  File "/home/sobirjonovmuhammadazizbek/course-bot/venv/lib/python3.11/site-packages/telebot/util.py", line 110, in raise_exceptions
    raise self.exception_info
  File "/home/sobirjonovmuhammadazizbek/course-bot/venv/lib/python3.11/site-packages/telebot/util.py", line 92, in run
    task(*args, **kwargs)
  File "/home/sobirjonovmuhammadazizbek/course-bot/venv/lib/python3.11/site-packages/telebot/__init__.py", line 661, in __retrieve_updates
    updates = self.get_updates(offset=(self.last_update_id + 1),
             ^^^^^^^^^^^^^^^^^^^^^^^^^^^^^^^^^^^^^^^^^^^^^^^^^^^
  File "/home/sobirjonovmuhammadazizbek/course-bot/venv/lib/python3.11/site-packages/telebot/__init__.py", line 633, in get_updates
    json_updates = apihelper.get_updates(
                   ^^^^^^^^^^^^^^^^^^^^^^
  File "/home/sobirjonovmuhammadazizbek/course-bot/venv/lib/python3.11/site-packages/telebot/apihelper.py", line 321, in get_updates
    return _make_request(token, method_url, params=payload)
           ^^^^^^^^^^^^^^^^^^^^^^^^^^^^^^^^^^^^^^^^^^^^^^^^
  File "/home/sobirjonovmuhammadazizbek/course-bot/venv/lib/python3.11/site-packages/telebot/apihelper.py", line 164, in _make_request
    json_result = _check_result(method_name, result)
                  ^^^^^^^^^^^^^^^^^^^^^^^^^^^^^^^^^^
  File "/home/sobirjonovmuhammadazizbek/course-bot/venv/lib/python3.11/site-packages/telebot/apihelper.py", line 191, in _check_result
    raise ApiTelegramException(method_name, result, result_json)
telebot.apihelper.ApiTelegramException: A request to the Telegram API was unsuccessful. Error code: 409. Description: Conflict: terminated by other getUpdates request; make sure that only one bot instance is running
"
2024-04-04 08:53:24,715 (__init__.py:1147 MainThread) ERROR - TeleBot: "Threaded polling exception: A request to the Telegram API was unsuccessful. Error code: 409. Description: Conflict: terminated by other getUpdates request; make sure that only one bot instance is running"
2024-04-04 08:53:24,716 (__init__.py:1149 MainThread) ERROR - TeleBot: "Exception traceback:
Traceback (most recent call last):
  File "/home/sobirjonovmuhammadazizbek/course-bot/venv/lib/python3.11/site-packages/telebot/__init__.py", line 1140, in __threaded_polling
    polling_thread.raise_exceptions()
  File "/home/sobirjonovmuhammadazizbek/course-bot/venv/lib/python3.11/site-packages/telebot/util.py", line 110, in raise_exceptions
    raise self.exception_info
  File "/home/sobirjonovmuhammadazizbek/course-bot/venv/lib/python3.11/site-packages/telebot/util.py", line 92, in run
    task(*args, **kwargs)
  File "/home/sobirjonovmuhammadazizbek/course-bot/venv/lib/python3.11/site-packages/telebot/__init__.py", line 661, in __retrieve_updates
    updates = self.get_updates(offset=(self.last_update_id + 1),
             ^^^^^^^^^^^^^^^^^^^^^^^^^^^^^^^^^^^^^^^^^^^^^^^^^^^
  File "/home/sobirjonovmuhammadazizbek/course-bot/venv/lib/python3.11/site-packages/telebot/__init__.py", line 633, in get_updates
    json_updates = apihelper.get_updates(
                   ^^^^^^^^^^^^^^^^^^^^^^
  File "/home/sobirjonovmuhammadazizbek/course-bot/venv/lib/python3.11/site-packages/telebot/apihelper.py", line 321, in get_updates
    return _make_request(token, method_url, params=payload)
           ^^^^^^^^^^^^^^^^^^^^^^^^^^^^^^^^^^^^^^^^^^^^^^^^
  File "/home/sobirjonovmuhammadazizbek/course-bot/venv/lib/python3.11/site-packages/telebot/apihelper.py", line 164, in _make_request
    json_result = _check_result(method_name, result)
                  ^^^^^^^^^^^^^^^^^^^^^^^^^^^^^^^^^^
  File "/home/sobirjonovmuhammadazizbek/course-bot/venv/lib/python3.11/site-packages/telebot/apihelper.py", line 191, in _check_result
    raise ApiTelegramException(method_name, result, result_json)
telebot.apihelper.ApiTelegramException: A request to the Telegram API was unsuccessful. Error code: 409. Description: Conflict: terminated by other getUpdates request; make sure that only one bot instance is running
"
2024-04-04 08:53:25,861 (__init__.py:1147 MainThread) ERROR - TeleBot: "Threaded polling exception: A request to the Telegram API was unsuccessful. Error code: 409. Description: Conflict: terminated by other getUpdates request; make sure that only one bot instance is running"
2024-04-04 08:53:25,861 (__init__.py:1149 MainThread) ERROR - TeleBot: "Exception traceback:
Traceback (most recent call last):
  File "/home/sobirjonovmuhammadazizbek/course-bot/venv/lib/python3.11/site-packages/telebot/__init__.py", line 1140, in __threaded_polling
    polling_thread.raise_exceptions()
  File "/home/sobirjonovmuhammadazizbek/course-bot/venv/lib/python3.11/site-packages/telebot/util.py", line 110, in raise_exceptions
    raise self.exception_info
  File "/home/sobirjonovmuhammadazizbek/course-bot/venv/lib/python3.11/site-packages/telebot/util.py", line 92, in run
    task(*args, **kwargs)
  File "/home/sobirjonovmuhammadazizbek/course-bot/venv/lib/python3.11/site-packages/telebot/__init__.py", line 661, in __retrieve_updates
    updates = self.get_updates(offset=(self.last_update_id + 1),
             ^^^^^^^^^^^^^^^^^^^^^^^^^^^^^^^^^^^^^^^^^^^^^^^^^^^
  File "/home/sobirjonovmuhammadazizbek/course-bot/venv/lib/python3.11/site-packages/telebot/__init__.py", line 633, in get_updates
    json_updates = apihelper.get_updates(
                   ^^^^^^^^^^^^^^^^^^^^^^
  File "/home/sobirjonovmuhammadazizbek/course-bot/venv/lib/python3.11/site-packages/telebot/apihelper.py", line 321, in get_updates
    return _make_request(token, method_url, params=payload)
           ^^^^^^^^^^^^^^^^^^^^^^^^^^^^^^^^^^^^^^^^^^^^^^^^
  File "/home/sobirjonovmuhammadazizbek/course-bot/venv/lib/python3.11/site-packages/telebot/apihelper.py", line 164, in _make_request
    json_result = _check_result(method_name, result)
                  ^^^^^^^^^^^^^^^^^^^^^^^^^^^^^^^^^^
  File "/home/sobirjonovmuhammadazizbek/course-bot/venv/lib/python3.11/site-packages/telebot/apihelper.py", line 191, in _check_result
    raise ApiTelegramException(method_name, result, result_json)
telebot.apihelper.ApiTelegramException: A request to the Telegram API was unsuccessful. Error code: 409. Description: Conflict: terminated by other getUpdates request; make sure that only one bot instance is running
"
2024-04-04 08:53:31,009 (__init__.py:1147 MainThread) ERROR - TeleBot: "Threaded polling exception: A request to the Telegram API was unsuccessful. Error code: 409. Description: Conflict: terminated by other getUpdates request; make sure that only one bot instance is running"
2024-04-04 08:53:31,010 (__init__.py:1149 MainThread) ERROR - TeleBot: "Exception traceback:
Traceback (most recent call last):
  File "/home/sobirjonovmuhammadazizbek/course-bot/venv/lib/python3.11/site-packages/telebot/__init__.py", line 1140, in __threaded_polling
    polling_thread.raise_exceptions()
  File "/home/sobirjonovmuhammadazizbek/course-bot/venv/lib/python3.11/site-packages/telebot/util.py", line 110, in raise_exceptions
    raise self.exception_info
  File "/home/sobirjonovmuhammadazizbek/course-bot/venv/lib/python3.11/site-packages/telebot/util.py", line 92, in run
    task(*args, **kwargs)
  File "/home/sobirjonovmuhammadazizbek/course-bot/venv/lib/python3.11/site-packages/telebot/__init__.py", line 661, in __retrieve_updates
    updates = self.get_updates(offset=(self.last_update_id + 1),
             ^^^^^^^^^^^^^^^^^^^^^^^^^^^^^^^^^^^^^^^^^^^^^^^^^^^
  File "/home/sobirjonovmuhammadazizbek/course-bot/venv/lib/python3.11/site-packages/telebot/__init__.py", line 633, in get_updates
    json_updates = apihelper.get_updates(
                   ^^^^^^^^^^^^^^^^^^^^^^
  File "/home/sobirjonovmuhammadazizbek/course-bot/venv/lib/python3.11/site-packages/telebot/apihelper.py", line 321, in get_updates
    return _make_request(token, method_url, params=payload)
           ^^^^^^^^^^^^^^^^^^^^^^^^^^^^^^^^^^^^^^^^^^^^^^^^
  File "/home/sobirjonovmuhammadazizbek/course-bot/venv/lib/python3.11/site-packages/telebot/apihelper.py", line 164, in _make_request
    json_result = _check_result(method_name, result)
                  ^^^^^^^^^^^^^^^^^^^^^^^^^^^^^^^^^^
  File "/home/sobirjonovmuhammadazizbek/course-bot/venv/lib/python3.11/site-packages/telebot/apihelper.py", line 191, in _check_result
    raise ApiTelegramException(method_name, result, result_json)
telebot.apihelper.ApiTelegramException: A request to the Telegram API was unsuccessful. Error code: 409. Description: Conflict: terminated by other getUpdates request; make sure that only one bot instance is running
"
2024-04-04 08:53:33,155 (__init__.py:1147 MainThread) ERROR - TeleBot: "Threaded polling exception: A request to the Telegram API was unsuccessful. Error code: 409. Description: Conflict: terminated by other getUpdates request; make sure that only one bot instance is running"
2024-04-04 08:53:33,155 (__init__.py:1149 MainThread) ERROR - TeleBot: "Exception traceback:
Traceback (most recent call last):
  File "/home/sobirjonovmuhammadazizbek/course-bot/venv/lib/python3.11/site-packages/telebot/__init__.py", line 1140, in __threaded_polling
    polling_thread.raise_exceptions()
  File "/home/sobirjonovmuhammadazizbek/course-bot/venv/lib/python3.11/site-packages/telebot/util.py", line 110, in raise_exceptions
    raise self.exception_info
  File "/home/sobirjonovmuhammadazizbek/course-bot/venv/lib/python3.11/site-packages/telebot/util.py", line 92, in run
    task(*args, **kwargs)
  File "/home/sobirjonovmuhammadazizbek/course-bot/venv/lib/python3.11/site-packages/telebot/__init__.py", line 661, in __retrieve_updates
    updates = self.get_updates(offset=(self.last_update_id + 1),
             ^^^^^^^^^^^^^^^^^^^^^^^^^^^^^^^^^^^^^^^^^^^^^^^^^^^
  File "/home/sobirjonovmuhammadazizbek/course-bot/venv/lib/python3.11/site-packages/telebot/__init__.py", line 633, in get_updates
    json_updates = apihelper.get_updates(
                   ^^^^^^^^^^^^^^^^^^^^^^
  File "/home/sobirjonovmuhammadazizbek/course-bot/venv/lib/python3.11/site-packages/telebot/apihelper.py", line 321, in get_updates
    return _make_request(token, method_url, params=payload)
           ^^^^^^^^^^^^^^^^^^^^^^^^^^^^^^^^^^^^^^^^^^^^^^^^
  File "/home/sobirjonovmuhammadazizbek/course-bot/venv/lib/python3.11/site-packages/telebot/apihelper.py", line 164, in _make_request
    json_result = _check_result(method_name, result)
                  ^^^^^^^^^^^^^^^^^^^^^^^^^^^^^^^^^^
  File "/home/sobirjonovmuhammadazizbek/course-bot/venv/lib/python3.11/site-packages/telebot/apihelper.py", line 191, in _check_result
    raise ApiTelegramException(method_name, result, result_json)
telebot.apihelper.ApiTelegramException: A request to the Telegram API was unsuccessful. Error code: 409. Description: Conflict: terminated by other getUpdates request; make sure that only one bot instance is running
"
2024-04-04 08:53:37,306 (__init__.py:1147 MainThread) ERROR - TeleBot: "Threaded polling exception: A request to the Telegram API was unsuccessful. Error code: 409. Description: Conflict: terminated by other getUpdates request; make sure that only one bot instance is running"
2024-04-04 08:53:37,307 (__init__.py:1149 MainThread) ERROR - TeleBot: "Exception traceback:
Traceback (most recent call last):
  File "/home/sobirjonovmuhammadazizbek/course-bot/venv/lib/python3.11/site-packages/telebot/__init__.py", line 1140, in __threaded_polling
    polling_thread.raise_exceptions()
  File "/home/sobirjonovmuhammadazizbek/course-bot/venv/lib/python3.11/site-packages/telebot/util.py", line 110, in raise_exceptions
    raise self.exception_info
  File "/home/sobirjonovmuhammadazizbek/course-bot/venv/lib/python3.11/site-packages/telebot/util.py", line 92, in run
    task(*args, **kwargs)
  File "/home/sobirjonovmuhammadazizbek/course-bot/venv/lib/python3.11/site-packages/telebot/__init__.py", line 661, in __retrieve_updates
    updates = self.get_updates(offset=(self.last_update_id + 1),
             ^^^^^^^^^^^^^^^^^^^^^^^^^^^^^^^^^^^^^^^^^^^^^^^^^^^
  File "/home/sobirjonovmuhammadazizbek/course-bot/venv/lib/python3.11/site-packages/telebot/__init__.py", line 633, in get_updates
    json_updates = apihelper.get_updates(
                   ^^^^^^^^^^^^^^^^^^^^^^
  File "/home/sobirjonovmuhammadazizbek/course-bot/venv/lib/python3.11/site-packages/telebot/apihelper.py", line 321, in get_updates
    return _make_request(token, method_url, params=payload)
           ^^^^^^^^^^^^^^^^^^^^^^^^^^^^^^^^^^^^^^^^^^^^^^^^
  File "/home/sobirjonovmuhammadazizbek/course-bot/venv/lib/python3.11/site-packages/telebot/apihelper.py", line 164, in _make_request
    json_result = _check_result(method_name, result)
                  ^^^^^^^^^^^^^^^^^^^^^^^^^^^^^^^^^^
  File "/home/sobirjonovmuhammadazizbek/course-bot/venv/lib/python3.11/site-packages/telebot/apihelper.py", line 191, in _check_result
    raise ApiTelegramException(method_name, result, result_json)
telebot.apihelper.ApiTelegramException: A request to the Telegram API was unsuccessful. Error code: 409. Description: Conflict: terminated by other getUpdates request; make sure that only one bot instance is running
"
2024-04-04 08:53:41,451 (__init__.py:1147 MainThread) ERROR - TeleBot: "Threaded polling exception: A request to the Telegram API was unsuccessful. Error code: 409. Description: Conflict: terminated by other getUpdates request; make sure that only one bot instance is running"
2024-04-04 08:53:41,455 (__init__.py:1149 MainThread) ERROR - TeleBot: "Exception traceback:
Traceback (most recent call last):
  File "/home/sobirjonovmuhammadazizbek/course-bot/venv/lib/python3.11/site-packages/telebot/__init__.py", line 1140, in __threaded_polling
    polling_thread.raise_exceptions()
  File "/home/sobirjonovmuhammadazizbek/course-bot/venv/lib/python3.11/site-packages/telebot/util.py", line 110, in raise_exceptions
    raise self.exception_info
  File "/home/sobirjonovmuhammadazizbek/course-bot/venv/lib/python3.11/site-packages/telebot/util.py", line 92, in run
    task(*args, **kwargs)
  File "/home/sobirjonovmuhammadazizbek/course-bot/venv/lib/python3.11/site-packages/telebot/__init__.py", line 661, in __retrieve_updates
    updates = self.get_updates(offset=(self.last_update_id + 1),
             ^^^^^^^^^^^^^^^^^^^^^^^^^^^^^^^^^^^^^^^^^^^^^^^^^^^
  File "/home/sobirjonovmuhammadazizbek/course-bot/venv/lib/python3.11/site-packages/telebot/__init__.py", line 633, in get_updates
    json_updates = apihelper.get_updates(
                   ^^^^^^^^^^^^^^^^^^^^^^
  File "/home/sobirjonovmuhammadazizbek/course-bot/venv/lib/python3.11/site-packages/telebot/apihelper.py", line 321, in get_updates
    return _make_request(token, method_url, params=payload)
           ^^^^^^^^^^^^^^^^^^^^^^^^^^^^^^^^^^^^^^^^^^^^^^^^
  File "/home/sobirjonovmuhammadazizbek/course-bot/venv/lib/python3.11/site-packages/telebot/apihelper.py", line 164, in _make_request
    json_result = _check_result(method_name, result)
                  ^^^^^^^^^^^^^^^^^^^^^^^^^^^^^^^^^^
  File "/home/sobirjonovmuhammadazizbek/course-bot/venv/lib/python3.11/site-packages/telebot/apihelper.py", line 191, in _check_result
    raise ApiTelegramException(method_name, result, result_json)
telebot.apihelper.ApiTelegramException: A request to the Telegram API was unsuccessful. Error code: 409. Description: Conflict: terminated by other getUpdates request; make sure that only one bot instance is running
"
2024-04-04 08:53:49,606 (__init__.py:1147 MainThread) ERROR - TeleBot: "Threaded polling exception: A request to the Telegram API was unsuccessful. Error code: 409. Description: Conflict: terminated by other getUpdates request; make sure that only one bot instance is running"
2024-04-04 08:53:49,607 (__init__.py:1149 MainThread) ERROR - TeleBot: "Exception traceback:
Traceback (most recent call last):
  File "/home/sobirjonovmuhammadazizbek/course-bot/venv/lib/python3.11/site-packages/telebot/__init__.py", line 1140, in __threaded_polling
    polling_thread.raise_exceptions()
  File "/home/sobirjonovmuhammadazizbek/course-bot/venv/lib/python3.11/site-packages/telebot/util.py", line 110, in raise_exceptions
    raise self.exception_info
  File "/home/sobirjonovmuhammadazizbek/course-bot/venv/lib/python3.11/site-packages/telebot/util.py", line 92, in run
    task(*args, **kwargs)
  File "/home/sobirjonovmuhammadazizbek/course-bot/venv/lib/python3.11/site-packages/telebot/__init__.py", line 661, in __retrieve_updates
    updates = self.get_updates(offset=(self.last_update_id + 1),
             ^^^^^^^^^^^^^^^^^^^^^^^^^^^^^^^^^^^^^^^^^^^^^^^^^^^
  File "/home/sobirjonovmuhammadazizbek/course-bot/venv/lib/python3.11/site-packages/telebot/__init__.py", line 633, in get_updates
    json_updates = apihelper.get_updates(
                   ^^^^^^^^^^^^^^^^^^^^^^
  File "/home/sobirjonovmuhammadazizbek/course-bot/venv/lib/python3.11/site-packages/telebot/apihelper.py", line 321, in get_updates
    return _make_request(token, method_url, params=payload)
           ^^^^^^^^^^^^^^^^^^^^^^^^^^^^^^^^^^^^^^^^^^^^^^^^
  File "/home/sobirjonovmuhammadazizbek/course-bot/venv/lib/python3.11/site-packages/telebot/apihelper.py", line 164, in _make_request
    json_result = _check_result(method_name, result)
                  ^^^^^^^^^^^^^^^^^^^^^^^^^^^^^^^^^^
  File "/home/sobirjonovmuhammadazizbek/course-bot/venv/lib/python3.11/site-packages/telebot/apihelper.py", line 191, in _check_result
    raise ApiTelegramException(method_name, result, result_json)
telebot.apihelper.ApiTelegramException: A request to the Telegram API was unsuccessful. Error code: 409. Description: Conflict: terminated by other getUpdates request; make sure that only one bot instance is running
"
2024-04-04 08:53:57,751 (__init__.py:1147 MainThread) ERROR - TeleBot: "Threaded polling exception: A request to the Telegram API was unsuccessful. Error code: 409. Description: Conflict: terminated by other getUpdates request; make sure that only one bot instance is running"
2024-04-04 08:53:57,752 (__init__.py:1149 MainThread) ERROR - TeleBot: "Exception traceback:
Traceback (most recent call last):
  File "/home/sobirjonovmuhammadazizbek/course-bot/venv/lib/python3.11/site-packages/telebot/__init__.py", line 1140, in __threaded_polling
    polling_thread.raise_exceptions()
  File "/home/sobirjonovmuhammadazizbek/course-bot/venv/lib/python3.11/site-packages/telebot/util.py", line 110, in raise_exceptions
    raise self.exception_info
  File "/home/sobirjonovmuhammadazizbek/course-bot/venv/lib/python3.11/site-packages/telebot/util.py", line 92, in run
    task(*args, **kwargs)
  File "/home/sobirjonovmuhammadazizbek/course-bot/venv/lib/python3.11/site-packages/telebot/__init__.py", line 661, in __retrieve_updates
    updates = self.get_updates(offset=(self.last_update_id + 1),
             ^^^^^^^^^^^^^^^^^^^^^^^^^^^^^^^^^^^^^^^^^^^^^^^^^^^
  File "/home/sobirjonovmuhammadazizbek/course-bot/venv/lib/python3.11/site-packages/telebot/__init__.py", line 633, in get_updates
    json_updates = apihelper.get_updates(
                   ^^^^^^^^^^^^^^^^^^^^^^
  File "/home/sobirjonovmuhammadazizbek/course-bot/venv/lib/python3.11/site-packages/telebot/apihelper.py", line 321, in get_updates
    return _make_request(token, method_url, params=payload)
           ^^^^^^^^^^^^^^^^^^^^^^^^^^^^^^^^^^^^^^^^^^^^^^^^
  File "/home/sobirjonovmuhammadazizbek/course-bot/venv/lib/python3.11/site-packages/telebot/apihelper.py", line 164, in _make_request
    json_result = _check_result(method_name, result)
                  ^^^^^^^^^^^^^^^^^^^^^^^^^^^^^^^^^^
  File "/home/sobirjonovmuhammadazizbek/course-bot/venv/lib/python3.11/site-packages/telebot/apihelper.py", line 191, in _check_result
    raise ApiTelegramException(method_name, result, result_json)
telebot.apihelper.ApiTelegramException: A request to the Telegram API was unsuccessful. Error code: 409. Description: Conflict: terminated by other getUpdates request; make sure that only one bot instance is running
"
2024-04-04 08:54:02,180 (__init__.py:1147 MainThread) ERROR - TeleBot: "Threaded polling exception: A request to the Telegram API was unsuccessful. Error code: 409. Description: Conflict: terminated by other getUpdates request; make sure that only one bot instance is running"
2024-04-04 08:54:02,181 (__init__.py:1149 MainThread) ERROR - TeleBot: "Exception traceback:
Traceback (most recent call last):
  File "/home/sobirjonovmuhammadazizbek/course-bot/venv/lib/python3.11/site-packages/telebot/__init__.py", line 1140, in __threaded_polling
    polling_thread.raise_exceptions()
  File "/home/sobirjonovmuhammadazizbek/course-bot/venv/lib/python3.11/site-packages/telebot/util.py", line 110, in raise_exceptions
    raise self.exception_info
  File "/home/sobirjonovmuhammadazizbek/course-bot/venv/lib/python3.11/site-packages/telebot/util.py", line 92, in run
    task(*args, **kwargs)
  File "/home/sobirjonovmuhammadazizbek/course-bot/venv/lib/python3.11/site-packages/telebot/__init__.py", line 661, in __retrieve_updates
    updates = self.get_updates(offset=(self.last_update_id + 1),
             ^^^^^^^^^^^^^^^^^^^^^^^^^^^^^^^^^^^^^^^^^^^^^^^^^^^
  File "/home/sobirjonovmuhammadazizbek/course-bot/venv/lib/python3.11/site-packages/telebot/__init__.py", line 633, in get_updates
    json_updates = apihelper.get_updates(
                   ^^^^^^^^^^^^^^^^^^^^^^
  File "/home/sobirjonovmuhammadazizbek/course-bot/venv/lib/python3.11/site-packages/telebot/apihelper.py", line 321, in get_updates
    return _make_request(token, method_url, params=payload)
           ^^^^^^^^^^^^^^^^^^^^^^^^^^^^^^^^^^^^^^^^^^^^^^^^
  File "/home/sobirjonovmuhammadazizbek/course-bot/venv/lib/python3.11/site-packages/telebot/apihelper.py", line 164, in _make_request
    json_result = _check_result(method_name, result)
                  ^^^^^^^^^^^^^^^^^^^^^^^^^^^^^^^^^^
  File "/home/sobirjonovmuhammadazizbek/course-bot/venv/lib/python3.11/site-packages/telebot/apihelper.py", line 191, in _check_result
    raise ApiTelegramException(method_name, result, result_json)
telebot.apihelper.ApiTelegramException: A request to the Telegram API was unsuccessful. Error code: 409. Description: Conflict: terminated by other getUpdates request; make sure that only one bot instance is running
"
2024-04-04 08:54:17,403 (__init__.py:1147 MainThread) ERROR - TeleBot: "Threaded polling exception: A request to the Telegram API was unsuccessful. Error code: 409. Description: Conflict: terminated by other getUpdates request; make sure that only one bot instance is running"
2024-04-04 08:54:17,405 (__init__.py:1149 MainThread) ERROR - TeleBot: "Exception traceback:
Traceback (most recent call last):
  File "/home/sobirjonovmuhammadazizbek/course-bot/venv/lib/python3.11/site-packages/telebot/__init__.py", line 1140, in __threaded_polling
    polling_thread.raise_exceptions()
  File "/home/sobirjonovmuhammadazizbek/course-bot/venv/lib/python3.11/site-packages/telebot/util.py", line 110, in raise_exceptions
    raise self.exception_info
  File "/home/sobirjonovmuhammadazizbek/course-bot/venv/lib/python3.11/site-packages/telebot/util.py", line 92, in run
    task(*args, **kwargs)
  File "/home/sobirjonovmuhammadazizbek/course-bot/venv/lib/python3.11/site-packages/telebot/__init__.py", line 661, in __retrieve_updates
    updates = self.get_updates(offset=(self.last_update_id + 1),
             ^^^^^^^^^^^^^^^^^^^^^^^^^^^^^^^^^^^^^^^^^^^^^^^^^^^
  File "/home/sobirjonovmuhammadazizbek/course-bot/venv/lib/python3.11/site-packages/telebot/__init__.py", line 633, in get_updates
    json_updates = apihelper.get_updates(
                   ^^^^^^^^^^^^^^^^^^^^^^
  File "/home/sobirjonovmuhammadazizbek/course-bot/venv/lib/python3.11/site-packages/telebot/apihelper.py", line 321, in get_updates
    return _make_request(token, method_url, params=payload)
           ^^^^^^^^^^^^^^^^^^^^^^^^^^^^^^^^^^^^^^^^^^^^^^^^
  File "/home/sobirjonovmuhammadazizbek/course-bot/venv/lib/python3.11/site-packages/telebot/apihelper.py", line 164, in _make_request
    json_result = _check_result(method_name, result)
                  ^^^^^^^^^^^^^^^^^^^^^^^^^^^^^^^^^^
  File "/home/sobirjonovmuhammadazizbek/course-bot/venv/lib/python3.11/site-packages/telebot/apihelper.py", line 191, in _check_result
    raise ApiTelegramException(method_name, result, result_json)
telebot.apihelper.ApiTelegramException: A request to the Telegram API was unsuccessful. Error code: 409. Description: Conflict: terminated by other getUpdates request; make sure that only one bot instance is running
"
